Workbook

Sheet Mesa 1
A1: Componente EAP | B1: Amanda | C1: Cláudio | D1: Diogo | E1: Guilherme | F1: Lais | G1: Lucas | H1: Madu | I1: Média | J1: Valor Concordado | K1: Justificativa
A2: 1.1.1 Layout da Página Principal | B2: =Amanda!B2 -> 3 | C2: =Claudio!B2 -> 2 | D2: =Diogo!B2 -> 1 | E2: =Guilherme!B2 -> 2 | F2: =Lais!B2 -> 3 | G2: =Lucas!B2 -> 5 | H2: =Madu!B2 -> 2 | I2: =ROUND(AVERAGE(B2:H2),2 ) -> 2.57 | J2: 2.5
A3: 1.1.2 Botões com Roteamento | B3: =Amanda!B3 -> 1 | C3: =Claudio!B3 -> 1 | D3: =Diogo!B3 -> 1 | E3: =Guilherme!B3 -> 2 | F3: =Lais!B3 -> 2 | G3: =Lucas!B3 -> 0.5 | H3: =Madu!B3 -> 1 | I3: =ROUND(AVERAGE(B3:H3),2 ) -> 1.21 | J3: 1
A4: 1.1.3 Objeto (Peão) 3D | B4: =Amanda!B4 -> 2 | C4: =Claudio!B4 -> 8 | D4: =Diogo!B4 -> 3 | E4: =Guilherme!B4 -> 5 | F4: =Lais!B4 -> 1 | G4: =Lucas!B4 -> 3 | H4: =Madu!B4 -> 3 | I4: =ROUND(AVERAGE(B4:H4),2 ) -> 3.57 | J4: 5 | K4: Concordamos com o Guilherme, precisa de integração...
A5: 1.2.1 Layout da Página da Partida | B5: =Amanda!B5 -> 2 | C5: =Claudio!B5 -> 2 | D5: =Diogo!B5 -> 3 | E5: =Guilherme!B5 -> 3 | F5: =Lais!B5 -> 3 | G5: =Lucas!B5 -> 5 | H5: =Madu!B5 -> 1 | I5: =ROUND(AVERAGE(B5:H5),2 ) -> 2.71 | J5: 3
A6: 1.2.2.1 Componente do Tabuleiro com Jogadores | B6: =Amanda!B6 -> 5 | C6: =Claudio!B6 -> 8 | D6: =Diogo!B6 -> 1 | E6: =Guilherme!B6 -> 3 | F6: =Lais!B6 -> 5 | G6: 1 | H6: =Madu!B6 -> 3 | I6: =ROUND(AVERAGE(B6:H6),2 ) -> 3.71 | J6: 5
A7: 1.2.2.2 Componentes das Peças | B7: =Amanda!B7 -> 3 | C7: =Claudio!B7 -> 8 | D7: =Diogo!B7 -> 2 | E7: =Guilherme!B7 -> 2 | F7: =Lais!B7 -> 3 | G7: =Lucas!B7 -> 0.5 | H7: =Madu!B7 -> 3 | I7: =ROUND(AVERAGE(B7:H7),2 ) -> 3.07 | J7: 3
A8: 1.2.2.3 Componente do Relógio | B8: =Amanda!B8 -> 1 | C8: =Claudio!B8 -> 5 | D8: =Diogo!B8 -> 1 | E8: =Guilherme!B8 -> 1 | F8: =Lais!B8 -> 3 | G8: =Lucas!B8 -> 0.5 | H8: =Madu!B8 -> 3 | I8: =ROUND(AVERAGE(B8:H8),2 ) -> 2.07 | J8: 2
A9: 1.2.2.4 Componente do Histórico de Jogadas | B9: =Amanda!B9 -> 3 | C9: =Claudio!B9 -> 5 | D9: =Diogo!B9 -> 2 | E9: =Guilherme!B9 -> 2 | F9: =Lais!B9 -> 2 | G9: =Lucas!B9 -> 2 | H9: =Madu!B9 -> 3 | I9: =ROUND(AVERAGE(B9:H9),2 ) -> 2.71 | J9: 3
A10: 1.2.2.5 Componente "Pop-Up" de Vitória/Derrota/Empate | B10: =Amanda!B10 -> 1 | C10: =Claudio!B10 -> 3 | D10: =Diogo!B10 -> 1 | E10: =Guilherme!B10 -> 1 | F10: =Lais!B10 -> 1 | G10: =Lucas!B10 -> 0.5 | H10: =Madu!B10 -> 2 | I10: =ROUND(AVERAGE(B10:H10),2 ) -> 1.36 | J10: 1
A11: 1.2.3.1 Mecanismo de Pausa | B11: =Amanda!B11 -> 1 | C11: =Claudio!B11 -> 3 | D11: =Diogo!B11 -> 1 | E11: =Guilherme!B11 -> 2 | F11: =Lais!B11 -> 2 | G11: =Lucas!B11 -> ? | H11: =Madu!B11 -> 2 | I11: =ROUND(AVERAGE(B11:H11),2 ) -> 1.83 | J11: 2
A12: 1.2.3.2 Mecanismo de Desistência | B12: =Amanda!B12 -> 1 | C12: =Claudio!B12 -> 3 | D12: =Diogo!B12 -> 2 | E12: =Guilherme!B12 -> 0.5 | F12: =Lais!B12 -> 1 | G12: =Lucas!B12 -> 0.5 | H12: =Madu!B12 -> 2 | I12: =ROUND(AVERAGE(B12:H12),2 ) -> 1.43 | J12: 1.5
A13: 1.3.1 Layout da Página de Opções | B13: =Amanda!B13 -> 1 | C13: =Claudio!B13 -> 2 | D13: =Diogo!B13 -> 2 | E13: =Guilherme!B13 -> 0 | F13: =Lais!B13 -> 2 | G13: =Lucas!B13 -> 2 | H13: =Madu!B13 -> 1 | I13: =ROUND(AVERAGE(B13:H13),2 ) -> 1.43 | J13: 2
A14: 1.3.2 Componente com Controle de Volume | B14: =Amanda!B14 -> 1 | C14: =Claudio!B14 -> 8 | D14: =Diogo!B14 -> 1 | E14: =Guilherme!B14 -> 1 | F14: =Lais!B14 -> 1 | G14: =Lucas!B14 -> 0.5 | H14: =Madu!B14 -> 1 | I14: =ROUND(AVERAGE(B14:H14),2 ) -> 1.93 | J14: 1 | K14: Justificativa de Cláudio: Estava considerendo o estudo do controle de volume com elementos da Web.
A15: 1.3.3 Seletor de Tema | B15: =Amanda!B15 -> 1 | C15: =Claudio!B15 -> 2 | D15: =Diogo!B15 -> 1 | E15: =Guilherme!B15 -> 1 | F15: =Lais!B15 -> 1 | G15: =Lucas!B15 -> 0.5 | H15: =Madu!B15 -> 2 | I15: =ROUND(AVERAGE(B15:H15),2 ) -> 1.21 | J15: 1
A16: 1.3.4 Seletor de Oponente (Dificuldade) | B16: =Amanda!B16 -> 1 | C16: =Claudio!B16 -> 5 | D16: =Diogo!B16 -> 1 | E16: =Guilherme!B16 -> 0.5 | F16: =Lais!B16 -> 1 | G16: =Lucas!B16 -> 0.5 | H16: =Madu!B16 -> 1 | I16: =ROUND(AVERAGE(B16:H16),2 ) -> 1.43 | J16: 1 | K16: A lógica está na IA, só precisa lidar com a integração
A17: 1.4.1 Layout da Página de Créditos | B17: =Amanda!B17 -> 2 | C17: =Claudio!B17 -> 2 | D17: =Diogo!B17 -> 2 | E17: =Guilherme!B17 -> 0.5 | F17: =Lais!B17 -> 1 | G17: =Lucas!B17 -> 0.5 | H17: =Madu!B17 -> 1 | I17: =ROUND(AVERAGE(B17:H17),2 ) -> 1.29 | J17: 1
A18: 1.4.2 Exibição das Tecnologias/Técnicas do Projeto | B18: =Amanda!B18 -> 2 | C18: =Claudio!B18 -> 1 | D18: =Diogo!B18 -> 1 | E18: =Guilherme!B18 -> 0.5 | F18: =Lais!B18 -> 1 | G18: =Lucas!B18 -> 0.5 | H18: =Madu!B18 -> 0.5 | I18: =ROUND(AVERAGE(B18:H18),2 ) -> 0.93 | J18: 1
A19: 1.4.3 Exibição da Equipe | B19: =Amanda!B19 -> 1 | C19: =Claudio!B19 -> 1 | D19: =Diogo!B19 -> 1 | E19: =Guilherme!B19 -> 0 | F19: =Lais!B19 -> 1 | G19: =Lucas!B19 -> 0.5 | H19: =Madu!B19 -> 0.5 | I19: =ROUND(AVERAGE(B19:H19),2 ) -> 0.71 | J19: 1
A20: 1.5.1 Layout da Página de Perfil | B20: =Amanda!B20 -> 1 | C20: =Claudio!B20 -> 2 | D20: =Diogo!B20 -> 1 | E20: =Guilherme!B20 -> 1 | F20: =Lais!B20 -> 2 | G20: =Lucas!B20 -> 2 | H20: =Madu!B20 -> 1 | I20: =ROUND(AVERAGE(B20:H20),2 ) -> 1.43 | J20: 1.5
A21: 1.5.2 Exibição do Histórico de Partidas | B21: =Amanda!B21 -> 2 | C21: =Claudio!B21 -> 2 | D21: =Diogo!B21 -> 1 | E21: =Guilherme!B21 -> 1 | F21: =Lais!B21 -> 3 | G21: =Lucas!B21 -> 0.5 | H21: =Madu!B21 -> 0.5 | I21: =ROUND(AVERAGE(B21:H21),2 ) -> 1.43 | J21: 1.5
A22: 1.6.1 Layout da Página de Cadastro | B22: =Amanda!B22 -> 2 | C22: =Claudio!B22 -> 2 | D22: =Diogo!B22 -> 2 | E22: =Guilherme!B22 -> 1 | F22: =Lais!B22 -> 1 | G22: =Lucas!B22 -> 0.5 | H22: =Madu!B22 -> 0.5 | I22: =ROUND(AVERAGE(B22:H22),2 ) -> 1.29 | J22: 1
A23: 1.6.2 Formulário de Cadastro | B23: =Amanda!B23 -> 2 | C23: =Claudio!B23 -> 2 | D23: =Diogo!B23 -> 1 | E23: =Guilherme!B23 -> 1 | F23: =Lais!B23 -> 2 | G23: =Lucas!B23 -> 0.5 | H23: =Madu!B23 -> 1 | I23: =ROUND(AVERAGE(B23:H23),2 ) -> 1.36 | J23: 1
A24: 1.6.3 Lógica de Cadastro | B24: =Amanda!B24 -> 5 | C24: =Claudio!B24 -> 3 | D24: =Diogo!B24 -> 2 | E24: =Guilherme!B24 -> 3 | F24: =Lais!B24 -> 2 | G24: =Lucas!B24 -> 0.5 | H24: =Madu!B24 -> 1 | I24: =ROUND(AVERAGE(B24:H24),2 ) -> 2.36 | J24: 3 | K24: Precisa fazer conexão com o firebase, criar a tabela, lógica...
A25: 1.7.1 Layout da Página de Login | B25: =Amanda!B25 -> 2 | C25: =Claudio!B25 -> 2 | D25: =Diogo!B25 -> 2 | E25: =Guilherme!B25 -> 1 | F25: =Lais!B25 -> 1 | G25: =Lucas!B25 -> 0.5 | H25: =Madu!B25 -> 0.5 | I25: =ROUND(AVERAGE(B25:H25),2 ) -> 1.29 | J25: 1
A26: 1.7.2 Formulário de Login | B26: =Amanda!B26 -> 2 | C26: =Claudio!B26 -> 2 | D26: =Diogo!B26 -> 1 | E26: =Guilherme!B26 -> 1 | F26: =Lais!B26 -> 2 | G26: =Lucas!B26 -> 0.5 | H26: =Madu!B26 -> 1 | I26: =ROUND(AVERAGE(B26:H26),2 ) -> 1.36 | J26: 1
A27: 1.7.3 Lógica de Login | B27: =Amanda!B27 -> 3 | C27: =Claudio!B27 -> 3 | D27: =Diogo!B27 -> 2 | E27: =Guilherme!B27 -> 3 | F27: =Lais!B27 -> 2 | G27: =Lucas!B27 -> 0.5 | H27: =Madu!B27 -> 3 | I27: =ROUND(AVERAGE(B27:H27),2 ) -> 2.36 | J27: 2
A28: 2.1.1.1 Regras do Peão | B28: =Amanda!B28 -> 2 | C28: =Claudio!B28 -> 1 | D28: =Diogo!B28 -> 2 | E28: =Guilherme!B28 -> 0.5 | F28: =Lais!B28 -> 5 | G28: =Lucas!B28 -> 2 | H28: =Madu!B28 -> 2 | I28: =ROUND(AVERAGE(B28:H28),2 ) -> 2.07 | J28: 1
A29: 2.1.1.2 Regras da Torre | B29: =Amanda!B29 -> 2 | C29: =Claudio!B29 -> 1 | D29: =Diogo!B29 -> 2 | E29: =Guilherme!B29 -> 0.5 | F29: =Lais!B29 -> 5 | G29: =Lucas!B29 -> 2 | H29: =Madu!B29 -> 2 | I29: =ROUND(AVERAGE(B29:H29),2 ) -> 2.07 | J29: 1
A30: 2.1.1.3 Regras do Cavalo | B30: =Amanda!B30 -> 2 | C30: =Claudio!B30 -> 1 | D30: =Diogo!B30 -> 2 | E30: =Guilherme!B30 -> 0.5 | F30: =Lais!B30 -> 5 | G30: =Lucas!B30 -> 2 | H30: =Madu!B30 -> 2 | I30: =ROUND(AVERAGE(B30:H30),2 ) -> 2.07 | J30: 1
A31: 2.1.1.4 Regras do Bispo | B31: =Amanda!B31 -> 2 | C31: =Claudio!B31 -> 1 | D31: =Diogo!B31 -> 2 | E31: =Guilherme!B31 -> 0.5 | F31: =Lais!B31 -> 3 | G31: =Lucas!B31 -> 2 | H31: =Madu!B31 -> 2 | I31: =ROUND(AVERAGE(B31:H31),2 ) -> 1.79 | J31: 1
A32: 2.1.1.5 Regras do Rei | B32: =Amanda!B32 -> 2 | C32: =Claudio!B32 -> 1 | D32: =Diogo!B32 -> 2 | E32: =Guilherme!B32 -> 2 | F32: =Lais!B32 -> 8 | G32: =Lucas!B32 -> 2 | H32: =Madu!B32 -> 2 | I32: =ROUND(AVERAGE(B32:H32),2 ) -> 2.71 | J32: 2
A33: 2.1.1.6 Regras da Rainha | B33: =Amanda!B33 -> 2 | C33: =Claudio!B33 -> 1 | D33: =Diogo!B33 -> 2 | E33: =Guilherme!B33 -> 0.5 | F33: =Lais!B33 -> 5 | G33: =Lucas!B33 -> 2 | H33: =Madu!B33 -> 2 | I33: =ROUND(AVERAGE(B33:H33),2 ) -> 2.07 | J33: 1
A34: 2.1.2.1 Lógica Roque | B34: =Amanda!B34 -> 2 | C34: =Claudio!B34 -> 2 | D34: =Diogo!B34 -> 3 | E34: =Guilherme!B34 -> 0.5 | F34: =Lais!B34 -> 5 | G34: =Lucas!B34 -> 2 | H34: =Madu!B34 -> 3 | I34: =ROUND(AVERAGE(B34:H34),2 ) -> 2.5 | J34: 2
A35: 2.1.2.2 Lógica En Passant | B35: =Amanda!B35 -> 2 | C35: =Claudio!B35 -> 2 | D35: =Diogo!B35 -> 3 | E35: =Guilherme!B35 -> 0.5 | F35: =Lais!B35 -> 5 | G35: =Lucas!B35 -> 2 | H35: =Madu!B35 -> 3 | I35: =ROUND(AVERAGE(B35:H35),2 ) -> 2.5 | J35: 2
A36: 2.1.2.3 Lógica Promoção do Peão | B36: =Amanda!B36 -> 2 | C36: =Claudio!B36 -> 2 | D36: =Diogo!B36 -> 2 | E36: =Guilherme!B36 -> 1 | F36: =Lais!B36 -> 3 | G36: =Lucas!B36 -> 2 | H36: =Madu!B36 -> 3 | I36: =ROUND(AVERAGE(B36:H36),2 ) -> 2.14 | J36: 2
... A52: 2.4.2 Testes de detecção do estado da partida | B52: =Amanda!B52 -> 3 | C52: =Claudio!B52 -> 5 | D52: =Diogo!B52 -> 8 | E52: =Guilherme!B52 -> 13 | F52: =Lais!B52 -> 2 | G52: =Lucas!B52 -> 8 | H52: =Madu!B52 -> 5 | I52: =ROUND(AVERAGE(B52:H52),2 ) -> 6.29 | J52: 5
A53: 3.1.1 Função de Avaliação | B53: =Amanda!B53 -> 5 | C53: =Claudio!B53 -> 5 | D53: =Diogo!B53 -> 2 | E53: =Guilherme!B53 -> ? | F53: =Lais!B53 -> 40 | G53: =Lucas!B53 -> ? | H53: =Madu!B53 -> 5 | I53: =ROUND(AVERAGE(B53:H53),2 ) -> 11.4 | J53: 5 | K53: * Seguindo Equipe da IA (Amanda e Madu)
A54: 3.1.2 Busca (Alpha-Beta) | B54: =Amanda!B54 -> 5 | C54: =Claudio!B54 -> 5 | D54: =Diogo!B54 -> 2 | E54: =Guilherme!B54 -> 13 | F54: =Lais!B54 -> 40 | G54: =Lucas!B54 -> ? | H54: =Madu!B54 -> 5 | I54: =ROUND(AVERAGE(B54:H54),2 ) -> 11.67 | J54: 5 | K54: * Seguindo Equipe da IA (Amanda e Madu)
A55: 3.1.3 Geração de Jogadas | B55: =Amanda!B55 -> 5 | C55: =Claudio!B55 -> 13 | D55: =Diogo!B55 -> 2 | E55: =Guilherme!B55 -> 8 | F55: =Lais!B55 -> 20 | G55: =Lucas!B55 -> 2 | H55: =Madu!B55 -> 5 | I55: =ROUND(AVERAGE(B55:H55),2 ) -> 7.86 | J55: 5 | K55: * Seguindo Equipe da IA (Amanda e Madu)
...

Sheet Mesa 2
A1: Componente EAP | B1: Amanda | C1: Cláudio | D1: Diogo | E1: Guilherme | F1: Lais | G1: Lucas | H1: Madu | I1: Média
A2: 1.1.1 Layout da Página Principal | I2: =ROUND(AVERAGE(B2:H2),2 ) -> #DIV/0!
A3: 1.1.2 Botões com Roteamento | I3: =ROUND(AVERAGE(B3:H3),2 ) -> #DIV/0!
A4: 1.1.3 Objeto (Peão) 3D | I4: =ROUND(AVERAGE(B4:H4),2 ) -> #DIV/0!
A5: 1.2.1 Layout da Página da Partida | I5: =ROUND(AVERAGE(B5:H5),2 ) -> #DIV/0!
A6: 1.2.2.1 Componente do Tabuleiro com Jogadores | I6: =ROUND(AVERAGE(B6:H6),2 ) -> #DIV/0!
A7: 1.2.2.2 Componentes das Peças | I7: =ROUND(AVERAGE(B7:H7),2 ) -> #DIV/0!
A8: 1.2.2.3 Componente do Relógio | I8: =ROUND(AVERAGE(B8:H8),2 ) -> #DIV/0!
A9: 1.2.2.4 Componente do Histórico de Jogadas | I9: =ROUND(AVERAGE(B9:H9),2 ) -> #DIV/0!
A10: 1.2.2.5 Componente "Pop-Up" de Vitória/Derrota/Empate | I10: =ROUND(AVERAGE(B10:H10),2 ) -> #DIV/0!
A11: 1.2.3.1 Mecanismo de Pausa | I11: =ROUND(AVERAGE(B11:H11),2 ) -> #DIV/0!
A12: 1.2.3.2 Mecanismo de Desistência | I12: =ROUND(AVERAGE(B12:H12),2 ) -> #DIV/0!
A13: 1.3.1 Layout da Página de Opções | I13: =ROUND(AVERAGE(B13:H13),2 ) -> #DIV/0!
... A77: 5.2 Testes E2E | I77: =ROUND(AVERAGE(B77:H77),2 ) -> #DIV/0!

Sheet Mesa 3
A1: Componente EAP | B1: Amanda | C1: Cláudio | D1: Diogo | E1: Guilherme | F1: Lais | G1: Lucas | H1: Madu | I1: Média
A2: 1.1.1 Layout da Página Principal | I2: =ROUND(AVERAGE(B2:H2),2 ) -> #DIV/0!
A3: 1.1.2 Botões com Roteamento | I3: =ROUND(AVERAGE(B3:H3),2 ) -> #DIV/0!
A4: 1.1.3 Objeto (Peão) 3D | I4: =ROUND(AVERAGE(B4:H4),2 ) -> #DIV/0!
A5: 1.2.1 Layout da Página da Partida | I5: =ROUND(AVERAGE(B5:H5),2 ) -> #DIV/0!
A6: 1.2.2.1 Componente do Tabuleiro com Jogadores | I6: =ROUND(AVERAGE(B6:H6),2 ) -> #DIV/0!
A7: 1.2.2.2 Componentes das Peças | I7: =ROUND(AVERAGE(B7:H7),2 ) -> #DIV/0!
A8: 1.2.2.3 Componente do Relógio | I8: =ROUND(AVERAGE(B8:H8),2 ) -> #DIV/0!
A9: 1.2.2.4 Componente do Histórico de Jogadas | I9: =ROUND(AVERAGE(B9:H9),2 ) -> #DIV/0!
A10: 1.2.2.5 Componente "Pop-Up" de Vitória/Derrota/Empate | I10: =ROUND(AVERAGE(B10:H10),2 ) -> #DIV/0!
A11: 1.2.3.1 Mecanismo de Pausa | I11: =ROUND(AVERAGE(B11:H11),2 ) -> #DIV/0!
A12: 1.2.3.2 Mecanismo de Desistência | I12: =ROUND(AVERAGE(B12:H12),2 ) -> #DIV/0!
A13: 1.3.1 Layout da Página de Opções | I13: =ROUND(AVERAGE(B13:H13),2 ) -> #DIV/0!
... A77: 5.2 Testes E2E | I77: =ROUND(AVERAGE(B77:H77),2 ) -> #DIV/0!

Sheet Amanda
A1: Componente EAP | B1: Amanda
A2: 1.1.1 Layout da Página Principal | B2: 3
A3: 1.1.2 Botões com Roteamento | B3: 1
A4: 1.1.3 Objeto (Peão) 3D | B4: 2
A5: 1.2.1 Layout da Página da Partida | B5: 2
A6: 1.2.2.1 Componente do Tabuleiro com Jogadores | B6: 5
A7: 1.2.2.2 Componentes das Peças | B7: 3
A8: 1.2.2.3 Componente do Relógio | B8: 1
A9: 1.2.2.4 Componente do Histórico de Jogadas | B9: 3
A10: 1.2.2.5 Componente "Pop-Up" de Vitória/Derrota/Empate | B10: 1
A11: 1.2.3.1 Mecanismo de Pausa | B11: 1
A12: 1.2.3.2 Mecanismo de Desistência | B12: 1
A13: 1.3.1 Layout da Página de Opções | B13: 1
... A77: 5.2 Testes E2E | B77: 5

Sheet Lais
A1: Componente EAP | B1: Lais
A2: 1.1.1 Layout da Página Principal | B2: 3
A3: 1.1.2 Botões com Roteamento | B3: 2
A4: 1.1.3 Objeto (Peão) 3D | B4: 1
A5: 1.2.1 Layout da Página da Partida | B5: 3
A6: 1.2.2.1 Componente do Tabuleiro com Jogadores | B6: 5
A7: 1.2.2.2 Componentes das Peças | B7: 3
A8: 1.2.2.3 Componente do Relógio | B8: 3
A9: 1.2.2.4 Componente do Histórico de Jogadas | B9: 2
A10: 1.2.2.5 Componente "Pop-Up" de Vitória/Derrota/Empate | B10: 1
A11: 1.2.3.1 Mecanismo de Pausa | B11: 2
A12: 1.2.3.2 Mecanismo de Desistência | B12: 1
A13: 1.3.1 Layout da Página de Opções | B13: 2
... A69: 4.2.2.3 3º Apresentação | B69: 20
A70: 4.2.3 Divisão de Tarefas | B70: ?
A71: 4.2.4 Monitoramento | B71: ?
A72: 4.3.1 Criação de Issues | B72: 5
A73: 4.3.2 Kanban | B73: ?
A74: 4.3.3 Roadmap (Gantt) | B74: ?
A75: 4.4 Análise de Risco | B75: ?
A76: 5.1 Testes de Integração | B76: ?
A77: 5.2 Testes E2E | B77: ?

Sheet Claudio
A1: Componente EAP | B1: Claudio
A2: 1.1.1 Layout da Página Principal | B2: 2
A3: 1.1.2 Botões com Roteamento | B3: 1
A4: 1.1.3 Objeto (Peão) 3D | B4: 8
A5: 1.2.1 Layout da Página da Partida | B5: 2
A6: 1.2.2.1 Componente do Tabuleiro com Jogadores | B6: 8
A7: 1.2.2.2 Componentes das Peças | B7: 8
A8: 1.2.2.3 Componente do Relógio | B8: 5
A9: 1.2.2.4 Componente do Histórico de Jogadas | B9: 5
A10: 1.2.2.5 Componente "Pop-Up" de Vitória/Derrota/Empate | B10: 3
A11: 1.2.3.1 Mecanismo de Pausa | B11: 3
A12: 1.2.3.2 Mecanismo de Desistência | B12: 3
A13: 1.3.1 Layout da Página de Opções | B13: 2
... A61: 3.3.3 Testes dos níveis de dificuldade | B61: 20
A62: 4.1.1 EAP
A63: 4.1.2.1 Planning Poker | B63: 8
A64: 4.1.2.2 APF | B64: 5
A65: 4.1.2.3 COCOMO | B65: 5
A66: 4.2.1 Reuniões Semanais | B66: 20
A67: 4.2.2.1 1º Apresentação | B67: 13
A68: 4.2.2.2 2º Apresentação | B68: 13
A69: 4.2.2.3 3º Apresentação | B69: 13
A70: 4.2.3 Divisão de Tarefas | B70: 1
A71: 4.2.4 Monitoramento | B71: ?
A72: 4.3.1 Criação de Issues | B72: 0.5
A73: 4.3.2 Kanban | B73: 0.5
A74: 4.3.3 Roadmap (Gantt) | B74: 3
A75: 4.4 Análise de Risco | B75: 8
A76: 5.1 Testes de Integração | B76: 40
A77: 5.2 Testes E2E | B77: 40

Sheet Guilherme
A1: Componente EAP | B1: Guilherme
A2: 1.1.1 Layout da Página Principal | B2: 2
A3: 1.1.2 Botões com Roteamento | B3: 2
A4: 1.1.3 Objeto (Peão) 3D | B4: 5
A5: 1.2.1 Layout da Página da Partida | B5: 3
A6: 1.2.2.1 Componente do Tabuleiro com Jogadores | B6: 3
A7: 1.2.2.2 Componentes das Peças | B7: 2
A8: 1.2.2.3 Componente do Relógio | B8: 1
A9: 1.2.2.4 Componente do Histórico de Jogadas | B9: 2
A10: 1.2.2.5 Componente "Pop-Up" de Vitória/Derrota/Empate | B10: 1
A11: 1.2.3.1 Mecanismo de Pausa | B11: 2
A12: 1.2.3.2 Mecanismo de Desistência | B12: 0.5
A13: 1.3.1 Layout da Página de Opções | B13: 0
... A41: 2.2.3 Controle do Turno | B41: 0.5
A42: 2.2.4 Armazenamento das peças disponíveis | B42: ?
A43: 2.3.1.1 Afogamento | B43: 2
A44: 2.3.1.2 Falta de Peças | B44: 1
A45: 2.3.1.3 50 lances | B45: 1
A46: 2.3.1.4 Tripla Repetição | B46: 5
A47: 2.3.2.1 Decretar Vitória/Derrota | B47: 1
A48: 2.3.2.2 Armazena Partida em Histórico | B48: 2
A49: 2.3.3.1 Bloquear movimentos desistentes | B49: ?
A50: 2.3.4.1 Bloquear movimento da peça cravada | B50: 1
A51: 2.4.1 Testes de Movimento | B51: 3
A52: 2.4.2 Testes de detecção do estado da partida | B52: 13
A53: 3.1.1 Função de Avaliação | B53: ?
A54: 3.1.2 Busca (Alpha-Beta) | B54: 13
A55: 3.1.3 Geração de Jogadas | B55: 8
A56: 3.2.1 Definição de Parâmetros por nível de dificuldade | B56: 8
A57: 3.2.2 Profundidade de busca | B57: 5
A58: 3.2.3 Critérios de Avaliação | B58: 5
A59: 3.3.1 Testes do algoritmo | B59: 5
A60: 3.3.2 Testes da função de avaliação | B60: 3
A61: 3.3.3 Testes dos níveis de dificuldade | B61: 3
A62: 4.1.1 EAP | B62: 0
A63: 4.1.2.1 Planning Poker | B63: 0
A64: 4.1.2.2 APF | B64: 0
A65: 4.1.2.3 COCOMO | B65: 0
A66: 4.2.1 Reuniões Semanais | B66: café
A67: 4.2.2.1 1º Apresentação | B67: ?
...

Sheet Diogo
A1: Componente EAP | B1: Diogo
A2: 1.1.1 Layout da Página Principal | B2: 1
A3: 1.1.2 Botões com Roteamento | B3: 1
A4: 1.1.3 Objeto (Peão) 3D | B4: 3
A5: 1.2.1 Layout da Página da Partida | B5: 3
A6: 1.2.2.1 Componente do Tabuleiro com Jogadores | B6: 1
A7: 1.2.2.2 Componentes das Peças | B7: 2
A8: 1.2.2.3 Componente do Relógio | B8: 1
A9: 1.2.2.4 Componente do Histórico de Jogadas | B9: 2
A10: 1.2.2.5 Componente "Pop-Up" de Vitória/Derrota/Empate | B10: 1
A11: 1.2.3.1 Mecanismo de Pausa | B11: 1
A12: 1.2.3.2 Mecanismo de Desistência | B12: 2
A13: 1.3.1 Layout da Página de Opções | B13: 2
... A48: 2.3.2.2 Armazena Partida em Histórico | B48: 3
A49: 2.3.3.1 Bloquear movimentos desistentes | B49: ?
A50: 2.3.4.1 Bloquear movimento da peça cravada | B50: ?
A51: 2.4.1 Testes de Movimento | B51: 8
A52: 2.4.2 Testes de detecção do estado da partida | B52: 8
A53: 3.1.1 Função de Avaliação | B53: 2
A54: 3.1.2 Busca (Alpha-Beta) | B54: 2
A55: 3.1.3 Geração de Jogadas | B55: 2
A56: 3.2.1 Definição de Parâmetros por nível de dificuldade | B56: 3
A57: 3.2.2 Profundidade de busca | B57: 2
A58: 3.2.3 Critérios de Avaliação | B58: 2
A59: 3.3.1 Testes do algoritmo | B59: 5
A60: 3.3.2 Testes da função de avaliação | B60: 5
A61: 3.3.3 Testes dos níveis de dificuldade | B61: 5
A62: 4.1.1 EAP | B62: 13
... A72: 4.3.1 Criação de Issues | B72: 1
A73: 4.3.2 Kanban | B73: ?
A74: 4.3.3 Roadmap (Gantt) | B74: 5
A75: 4.4 Análise de Risco | B75: 5
A76: 5.1 Testes de Integração | B76: ?
A77: 5.2 Testes E2E | B77: 5

Sheet Madu
A1: Componente EAP | B1: Madu
A2: 1.1.1 Layout da Página Principal | B2: 2
A3: 1.1.2 Botões com Roteamento | B3: 1
A4: 1.1.3 Objeto (Peão) 3D | B4: 3
A5: 1.2.1 Layout da Página da Partida | B5: 1
A6: 1.2.2.1 Componente do Tabuleiro com Jogadores | B6: 3
A7: 1.2.2.2 Componentes das Peças | B7: 3
A8: 1.2.2.3 Componente do Relógio | B8: 3
A9: 1.2.2.4 Componente do Histórico de Jogadas | B9: 3
A10: 1.2.2.5 Componente "Pop-Up" de Vitória/Derrota/Empate | B10: 2
A11: 1.2.3.1 Mecanismo de Pausa | B11: 2
A12: 1.2.3.2 Mecanismo de Desistência | B12: 2
A13: 1.3.1 Layout da Página de Opções | B13: 1
... A77: 5.2 Testes E2E | B77: 5

Sheet Lucas
A1: Componente EAP | B1: Lucas
A2: 1.1.1 Layout da Página Principal | B2: 5
A3: 1.1.2 Botões com Roteamento | B3: 0.5
A4: 1.1.3 Objeto (Peão) 3D | B4: 3
A5: 1.2.1 Layout da Página da Partida | B5: 5
A6: 1.2.2.1 Componente do Tabuleiro com Jogadores | B6: 1
A7: 1.2.2.2 Componentes das Peças | B7: 0.5
A8: 1.2.2.3 Componente do Relógio | B8: 0.5
A9: 1.2.2.4 Componente do Histórico de Jogadas | B9: 2
A10: 1.2.2.5 Componente "Pop-Up" de Vitória/Derrota/Empate | B10: 0.5
A11: 1.2.3.1 Mecanismo de Pausa | B11: ?
A12: 1.2.3.2 Mecanismo de Desistência | B12: 0.5
A13: 1.3.1 Layout da Página de Opções | B13: 2
A14: 1.3.2 Componente com Controle de Volume | B14: 0.5
A15: 1.3.3 Seletor de Tema | B15: 0.5
A16: 1.3.4 Seletor de Oponente (Dificuldade) | B16: 0.5
A17: 1.4.1 Layout da Página de Créditos | B17: 0.5
A18: 1.4.2 Exibição das Tecnologias/Técnicas do Projeto | B18: 0.5
A19: 1.4.3 Exibição da Equipe | B19: 0.5
A20: 1.5.1 Layout da Página de Perfil | B20: 2
A21: 1.5.2 Exibição do Histórico de Partidas | B21: 0.5
A22: 1.6.1 Layout da Página de Cadastro | B22: 0.5
A23: 1.6.2 Formulário de Cadastro | B23: 0.5
... A48: 2.3.2.2 Armazena Partida em Histórico | B48: 2
A49: 2.3.3.1 Bloquear movimentos desistentes | B49: 0.5 | C49: 2.3.3.1 = 2.3.1.1
A50: 2.3.4.1 Bloquear movimento da peça cravada | B50: 0.5
A51: 2.4.1 Testes de Movimento | B51: 5
A52: 2.4.2 Testes de detecção do estado da partida | B52: 8
A53: 3.1.1 Função de Avaliação | B53: ?
A54: 3.1.2 Busca (Alpha-Beta) | B54: ?
A55: 3.1.3 Geração de Jogadas | B55: 2
A56: 3.2.1 Definição de Parâmetros por nível de dificuldade | B56: ?
A57: 3.2.2 Profundidade de busca | B57: ?
A58: 3.2.3 Critérios de Avaliação | B58: ?
A59: 3.3.1 Testes do algoritmo | B59: 8
A60: 3.3.2 Testes da função de avaliação | B60: 8
A61: 3.3.3 Testes dos níveis de dificuldade | B61: 8
A62: 4.1.1 EAP | B62: 8
A63: 4.1.2.1 Planning Poker | B63: 3
A64: 4.1.2.2 APF | B64: 2
...
