Workbook

Sheet Base de Dados
A1: Componente EAP | B1: Valor de Esforço Real | C1: Valor de Esforço Planejado | D1: Custo Real | E1: Custo Planejado | F1: Concluída | G1: Iteração de Conclusão Real | H1: Iteração de Conclusão Planejada | I1: Data de Conclusão Real
A2: 1.1.1 Layout da Página Principal | B2: 1.5 | C2: 2.5 | D2: =B2*12.5 -> 18.75 | E2: =C2*12.5 -> 31.25 | F2: TRUE | G2: 5 | H2: 5 | I2: 46278
A3: 1.1.2 Botões com Roteamento | B3: 1 | C3: 1 | D3: =B3*12.5 -> 12.5 | E3: =C3*12.5 -> 12.5 | F3: TRUE | G3: 5 | H3: 5 | I3: 46278
A4: 1.1.3 Objeto (Peão) 3D | B4: 3 | C4: 5 | D4: =B4*12.5 -> 37.5 | E4: =C4*12.5 -> 62.5 | F4: TRUE | G4: 7 | H4: 7 | I4: 46289
A5: 1.2.1 Layout da Página da Partida | B5: 2 | C5: 3 | D5: =B5*12.5 -> 25 | E5: =C5*12.5 -> 37.5 | F5: TRUE | G5: 5 | H5: 5 | I5: 46278
A6: 1.2.2.1 Componente do Tabuleiro com Jogadores | B6: 3.5 | C6: 5 | D6: =B6*12.5 -> 43.75 | E6: =C6*12.5 -> 62.5 | F6: TRUE | G6: 7 | H6: 7 | I6: 46290
A7: 1.2.2.2 Componentes das Peças | B7: 2 | C7: 3 | D7: =B7*12.5 -> 25 | E7: =C7*12.5 -> 37.5 | F7: TRUE | G7: 6 | H7: 7 | I7: 46282
A8: 1.2.2.3 Componente do Relógio | B8: 0.5 | C8: 2 | D8: =B8*12.5 -> 6.25 | E8: =C8*12.5 -> 25 | F8: TRUE | G8: 8 | H8: 7 | I8: 46296
A9: 1.2.2.4 Componente do Histórico de Jogadas | B9: 1.5 | C9: 3 | D9: =B9*12.5 -> 18.75 | E9: =C9*12.5 -> 37.5 | F9: TRUE | G9: 8 | H9: 8 | I9: 46298
A10: 1.2.2.5 Componente "Pop-Up" de Vitória/Derrota/Empate | B10: 0.5 | C10: 1 | D10: =B10*12.5 -> 6.25 | E10: =C10*12.5 -> 12.5 | F10: TRUE | G10: 8 | H10: 9 | I10: 46296
A11: 1.2.3.1 Mecanismo de Pausa | B11: 0.5 | C11: 2 | D11: =B11*12.5 -> 6.25 | E11: =C11*12.5 -> 25 | F11: TRUE | G11: 8 | H11: 9 | I11: 46296
A12: 1.2.3.2 Mecanismo de Desistência | B12: 0.5 | C12: 1.5 | D12: =B12*12.5 -> 6.25 | E12: =C12*12.5 -> 18.75 | F12: TRUE | G12: 8 | H12: 9 | I12: 46296
A13: 1.3.1 Layout da Página de Opções | C13: 2 | D13: =B13*12.5 -> 0 | E13: =C13*12.5 -> 25 | F13: FALSE | H13: 8
A14: 1.3.2 Componente com Controle de Volume | C14: 1 | D14: =B14*12.5 -> 0 | E14: =C14*12.5 -> 12.5 | F14: FALSE | H14: 8
A15: 1.3.3 Seletor de Tema | B15: 1 | C15: 1 | D15: =B15*12.5 -> 12.5 | E15: =C15*12.5 -> 12.5 | F15: TRUE | G15: 5 | H15: 5 | I15: 46278
A16: 1.3.4 Seletor de Oponente (Dificuldade) | B16: 0.5 | C16: 1 | D16: =B16*12.5 -> 6.25 | E16: =C16*12.5 -> 12.5 | F16: TRUE | G16: 8 | H16: 9 | I16: 46298
A17: 1.4.1 Layout da Página de Créditos | B17: 1 | C17: 1 | D17: =B17*12.5 -> 12.5 | E17: =C17*12.5 -> 12.5 | F17: TRUE | G17: 5 | H17: 5 | I17: 46278
A18: 1.4.2 Exibição das Tecnologias/Técnicas do Projeto | B18: 1 | C18: 1 | D18: =B18*12.5 -> 12.5 | E18: =C18*12.5 -> 12.5 | F18: TRUE | G18: 5 | H18: 5 | I18: 46278
A19: 1.4.3 Exibição da Equipe | B19: 1 | C19: 1 | D19: =B19*12.5 -> 12.5 | E19: =C19*12.5 -> 12.5 | F19: TRUE | G19: 5 | H19: 5 | I19: 46278
A20: 1.5.1 Layout da Página de Perfil | B20: 1 | C20: 1.5 | D20: =B20*12.5 -> 12.5 | E20: =C20*12.5 -> 18.75 | F20: TRUE | G20: 8 | H20: 9 | I20: 46296
A21: 1.5.2 Exibição do Histórico de Partidas | B21: 1 | C21: 1.5 | D21: =B21*12.5 -> 12.5 | E21: =C21*12.5 -> 18.75 | F21: TRUE | G21: 8 | H21: 9 | I21: 46296
A22: 1.6.1 Layout da Página de Cadastro | B22: 0.5 | C22: 1 | D22: =B22*12.5 -> 6.25 | E22: =C22*12.5 -> 12.5 | F22: TRUE | G22: 8 | H22: 7 | I22: 46296
A23: 1.6.2 Formulário de Cadastro | B23: 0.5 | C23: 1 | D23: =B23*12.5 -> 6.25 | E23: =C23*12.5 -> 12.5 | F23: TRUE | G23: 8 | H23: 7 | I23: 46296
A24: 1.6.3 Lógica de Cadastro | B24: 1 | C24: 3 | D24: =B24*12.5 -> 12.5 | E24: =C24*12.5 -> 37.5 | F24: TRUE | G24: 8 | H24: 7 | I24: 46296
A25: 1.7.1 Layout da Página de Login | B25: 0.5 | C25: 1 | D25: =B25*12.5 -> 6.25 | E25: =C25*12.5 -> 12.5 | F25: TRUE | G25: 8 | H25: 7 | I25: 46296
A26: 1.7.2 Formulário de Login | B26: 0.5 | C26: 1 | D26: =B26*12.5 -> 6.25 | E26: =C26*12.5 -> 12.5 | F26: TRUE | G26: 8 | H26: 7 | I26: 46296
... A33: 2.1.1.6 Regras da Rainha | B33: 1 | C33: 1 | D33: =B33*12.5 -> 12.5 | E33: =C33*12.5 -> 12.5 | F33: TRUE | G33: 8 | H33: 7 | I33: 46296
A34: 2.1.2.1 Lógica Roque | C34: 2 | D34: =B34*12.5 -> 0 | E34: =C34*12.5 -> 25 | F34: FALSE | H34: 8
A35: 2.1.2.2 Lógica En Passant | C35: 2 | D35: =B35*12.5 -> 0 | E35: =C35*12.5 -> 25 | F35: FALSE | H35: 8
A36: 2.1.2.3 Lógica Promoção do Peão | C36: 2 | D36: =B36*12.5 -> 0 | E36: =C36*12.5 -> 25 | F36: FALSE | H36: 8
A37: 2.1.3 Captura de peças | B37: 2 | C37: 2 | D37: =B37*12.5 -> 25 | E37: =C37*12.5 -> 25 | F37: TRUE | G37: 8 | H37: 7 | I37: 46298
A38: 2.1.4 Cálculo de jogadas permitidas | B38: 4 | C38: 5 | D38: =B38*12.5 -> 50 | E38: =C38*12.5 -> 62.5 | F38: TRUE | G38: 8 | H38: 8 | I38: 46298
A39: 2.2.1 Armazenamento de jogadas | C39: 2 | D39: =B39*12.5 -> 0 | E39: =C39*12.5 -> 25 | F39: FALSE | H39: 9
A40: 2.2.2 Criar tabuleiro e posições das peças | B40: 2 | C40: 3 | D40: =B40*12.5 -> 25 | E40: =C40*12.5 -> 37.5 | F40: TRUE | G40: 8 | H40: 9 | I40: 46296
A41: 2.2.3 Controle do Turno | B41: 2 | C41: 2 | D41: =B41*12.5 -> 25 | E41: =C41*12.5 -> 25 | F41: TRUE | G41: 8 | H41: 9 | I41: 46298
A42: 2.2.4 Armazenamento das peças disponíveis | C42: 2 | D42: =B42*12.5 -> 0 | E42: =C42*12.5 -> 25 | F42: FALSE | H42: 9
A43: 2.3.1.1 Afogamento | C43: 2.5 | D43: =B43*12.5 -> 0 | E43: =C43*12.5 -> 31.25 | F43: FALSE | H43: 10
A44: 2.3.1.2 Falta de Peças | C44: 3 | D44: =B44*12.5 -> 0 | E44: =C44*12.5 -> 37.5 | F44: FALSE | H44: 10
A45: 2.3.1.3 50 lances | C45: 3 | D45: =B45*12.5 -> 0 | E45: =C45*12.5 -> 37.5 | F45: FALSE | H45: 10
A46: 2.3.1.4 Tripla Repetição | C46: 2 | D46: =B46*12.5 -> 0 | E46: =C46*12.5 -> 25 | F46: FALSE | H46: 10
...

Sheet Cálculo dos Valores
A1: Iteração | B1: PV | C1: EV | D1: AC | E1: SPI | F1: CPI | G1: SV | H1: CV
A2: 1 | B2: =SUMIFS('Base de Dados'!E2:E999,'Base de Dados'!H2:H999,">0",'Base de Dados'!H2:H999,"<="&A2,'Base de Dados'!A2:A999,"<>4.2.1 Reuniões Semanais")+(SUMIF('Base de Dados'!A2:A999,"4.2.1 Reuniões Semanais",'Base de Dados'!E2:E999)/16)*MIN(16,A2) -> 306.25 | C2: {=IF(INDEX('Dados do Burndown'!R2:R17,A2)+6>TODAY(),"",SUMIFS('Base de Dados'!E2:E999,'Base de Dados'!G2:G999,">0",'Base de Dados'!G2:G999,"<="&A2,'Base de Dados'!F2:F999,TRUE,'Base de Dados'!A2:A999,"<>4.2.1 Reuniões Semanais")+(SUMIF('Base de Dados'!A2:A999,"4.2.1 Reuniões Semanais",'Base de Dados'!E2:E999)/16)*MIN(16,A2))} -> 306.25 | D2: {=IF(INDEX('Dados do Burndown'!R2:R17,A2)+6>TODAY(),"",SUMIFS('Base de Dados'!D2:D999,'Base de Dados'!G2:G999,">0",'Base de Dados'!G2:G999,"<="&A2,'Base de Dados'!A2:A999,"<>4.2.1 Reuniões Semanais")+(SUMIF('Base de Dados'!A2:A999,"4.2.1 Reuniões Semanais",'Base de Dados'!E2:E999)/16)*MIN(16,A2))} -> 262.5 | E2: =IF(C2="","",IFERROR(C2/B2,"")) -> 1 | F2: =IF(OR(C2="",D2=""),"",IFERROR(C2/D2,"")) -> 1.1666667 | G2: =IF(C2="","",C2-B2) -> 0 | H2: =IF(OR(C2="",D2=""),"",C2-D2) -> 43.75
A3: 2 | B3: =SUMIFS('Base de Dados'!E2:E999,'Base de Dados'!H2:H999,">0",'Base de Dados'!H2:H999,"<="&A3,'Base de Dados'!A2:A999,"<>4.2.1 Reuniões Semanais")+(SUMIF('Base de Dados'!A2:A999,"4.2.1 Reuniões Semanais",'Base de Dados'!E2:E999)/16)*MIN(16,A3) -> 600 | C3: {=IF(INDEX('Dados do Burndown'!R2:R17,A3)+6>TODAY(),"",SUMIFS('Base de Dados'!E2:E999,'Base de Dados'!G2:G999,">0",'Base de Dados'!G2:G999,"<="&A3,'Base de Dados'!F2:F999,TRUE,'Base de Dados'!A2:A999,"<>4.2.1 Reuniões Semanais")+(SUMIF('Base de Dados'!A2:A999,"4.2.1 Reuniões Semanais",'Base de Dados'!E2:E999)/16)*MIN(16,A3))} -> 525 | D3: {=IF(INDEX('Dados do Burndown'!R2:R17,A3)+6>TODAY(),"",SUMIFS('Base de Dados'!D2:D999,'Base de Dados'!G2:G999,">0",'Base de Dados'!G2:G999,"<="&A3,'Base de Dados'!A2:A999,"<>4.2.1 Reuniões Semanais")+(SUMIF('Base de Dados'!A2:A999,"4.2.1 Reuniões Semanais",'Base de Dados'!E2:E999)/16)*MIN(16,A3))} -> 481.25 | E3: =IF(C3="","",IFERROR(C3/B3,"")) -> 0.875 | F3: =IF(OR(C3="",D3=""),"",IFERROR(C3/D3,"")) -> 1.0909091 | G3: =IF(C3="","",C3-B3) -> -75 | H3: =IF(OR(C3="",D3=""),"",C3-D3) -> 43.75
A4: 3 | B4: =SUMIFS('Base de Dados'!E2:E999,'Base de Dados'!H2:H999,">0",'Base de Dados'!H2:H999,"<="&A4,'Base de Dados'!A2:A999,"<>4.2.1 Reuniões Semanais")+(SUMIF('Base de Dados'!A2:A999,"4.2.1 Reuniões Semanais",'Base de Dados'!E2:E999)/16)*MIN(16,A4) -> 918.75 | C4: {=IF(INDEX('Dados do Burndown'!R2:R17,A4)+6>TODAY(),"",SUMIFS('Base de Dados'!E2:E999,'Base de Dados'!G2:G999,">0",'Base de Dados'!G2:G999,"<="&A4,'Base de Dados'!F2:F999,TRUE,'Base de Dados'!A2:A999,"<>4.2.1 Reuniões Semanais")+(SUMIF('Base de Dados'!A2:A999,"4.2.1 Reuniões Semanais",'Base de Dados'!E2:E999)/16)*MIN(16,A4))} -> 918.75 | D4: {=IF(INDEX('Dados do Burndown'!R2:R17,A4)+6>TODAY(),"",SUMIFS('Base de Dados'!D2:D999,'Base de Dados'!G2:G999,">0",'Base de Dados'!G2:G999,"<="&A4,'Base de Dados'!A2:A999,"<>4.2.1 Reuniões Semanais")+(SUMIF('Base de Dados'!A2:A999,"4.2.1 Reuniões Semanais",'Base de Dados'!E2:E999)/16)*MIN(16,A4))} -> 931.25 | E4: =IF(C4="","",IFERROR(C4/B4,"")) -> 1 | F4: =IF(OR(C4="",D4=""),"",IFERROR(C4/D4,"")) -> 0.98657718 | G4: =IF(C4="","",C4-B4) -> 0 | H4: =IF(OR(C4="",D4=""),"",C4-D4) -> -12.5
A5: 4 | B5: =SUMIFS('Base de Dados'!E2:E999,'Base de Dados'!H2:H999,">0",'Base de Dados'!H2:H999,"<="&A5,'Base de Dados'!A2:A999,"<>4.2.1 Reuniões Semanais")+(SUMIF('Base de Dados'!A2:A999,"4.2.1 Reuniões Semanais",'Base de Dados'!E2:E999)/16)*MIN(16,A5) -> 1175 | C5: {=IF(INDEX('Dados do Burndown'!R2:R17,A5)+6>TODAY(),"",SUMIFS('Base de Dados'!E2:E999,'Base de Dados'!G2:G999,">0",'Base de Dados'!G2:G999,"<="&A5,'Base de Dados'!F2:F999,TRUE,'Base de Dados'!A2:A999,"<>4.2.1 Reuniões Semanais")+(SUMIF('Base de Dados'!A2:A999,"4.2.1 Reuniões Semanais",'Base de Dados'!E2:E999)/16)*MIN(16,A5))} -> 1175 | D5: {=IF(INDEX('Dados do Burndown'!R2:R17,A5)+6>TODAY(),"",SUMIFS('Base de Dados'!D2:D999,'Base de Dados'!G2:G999,">0",'Base de Dados'!G2:G999,"<="&A5,'Base de Dados'!A2:A999,"<>4.2.1 Reuniões Semanais")+(SUMIF('Base de Dados'!A2:A999,"4.2.1 Reuniões Semanais",'Base de Dados'!E2:E999)/16)*MIN(16,A5))} -> 1212.5 | E5: =IF(C5="","",IFERROR(C5/B5,"")) -> 1 | F5: =IF(OR(C5="",D5=""),"",IFERROR(C5/D5,"")) -> 0.96907216 | G5: =IF(C5="","",C5-B5) -> 0 | H5: =IF(OR(C5="",D5=""),"",C5-D5) -> -37.5
A6: 5 | B6: =SUMIFS('Base de Dados'!E2:E999,'Base de Dados'!H2:H999,">0",'Base de Dados'!H2:H999,"<="&A6,'Base de Dados'!A2:A999,"<>4.2.1 Reuniões Semanais")+(SUMIF('Base de Dados'!A2:A999,"4.2.1 Reuniões Semanais",'Base de Dados'!E2:E999)/16)*MIN(16,A6) -> 1650 | C6: {=IF(INDEX('Dados do Burndown'!R2:R17,A6)+6>TODAY(),"",SUMIFS('Base de Dados'!E2:E999,'Base de Dados'!G2:G999,">0",'Base de Dados'!G2:G999,"<="&A6,'Base de Dados'!F2:F999,TRUE,'Base de Dados'!A2:A999,"<>4.2.1 Reuniões Semanais")+(SUMIF('Base de Dados'!A2:A999,"4.2.1 Reuniões Semanais",'Base de Dados'!E2:E999)/16)*MIN(16,A6))} -> 1587.5 | D6: {=IF(INDEX('Dados do Burndown'!R2:R17,A6)+6>TODAY(),"",SUMIFS('Base de Dados'!D2:D999,'Base de Dados'!G2:G999,">0",'Base de Dados'!G2:G999,"<="&A6,'Base de Dados'!A2:A999,"<>4.2.1 Reuniões Semanais")+(SUMIF('Base de Dados'!A2:A999,"4.2.1 Reuniões Semanais",'Base de Dados'!E2:E999)/16)*MIN(16,A6))} -> 1612.5 | E6: =IF(C6="","",IFERROR(C6/B6,"")) -> 0.96212121 | F6: =IF(OR(C6="",D6=""),"",IFERROR(C6/D6,"")) -> 0.98449612 | G6: =IF(C6="","",C6-B6) -> -62.5 | H6: =IF(OR(C6="",D6=""),"",C6-D6) -> -25
A7: 6 | B7: =SUMIFS('Base de Dados'!E2:E999,'Base de Dados'!H2:H999,">0",'Base de Dados'!H2:H999,"<="&A7,'Base de Dados'!A2:A999,"<>4.2.1 Reuniões Semanais")+(SUMIF('Base de Dados'!A2:A999,"4.2.1 Reuniões Semanais",'Base de Dados'!E2:E999)/16)*MIN(16,A7) -> 1912.5 | C7: {=IF(INDEX('Dados do Burndown'!R2:R17,A7)+6>TODAY(),"",SUMIFS('Base de Dados'!E2:E999,'Base de Dados'!G2:G999,">0",'Base de Dados'!G2:G999,"<="&A7,'Base de Dados'!F2:F999,TRUE,'Base de Dados'!A2:A999,"<>4.2.1 Reuniões Semanais")+(SUMIF('Base de Dados'!A2:A999,"4.2.1 Reuniões Semanais",'Base de Dados'!E2:E999)/16)*MIN(16,A7))} -> 1887.5 | D7: {=IF(INDEX('Dados do Burndown'!R2:R17,A7)+6>TODAY(),"",SUMIFS('Base de Dados'!D2:D999,'Base de Dados'!G2:G999,">0",'Base de Dados'!G2:G999,"<="&A7,'Base de Dados'!A2:A999,"<>4.2.1 Reuniões Semanais")+(SUMIF('Base de Dados'!A2:A999,"4.2.1 Reuniões Semanais",'Base de Dados'!E2:E999)/16)*MIN(16,A7))} -> 1900 | E7: =IF(C7="","",IFERROR(C7/B7,"")) -> 0.9869281 | F7: =IF(OR(C7="",D7=""),"",IFERROR(C7/D7,"")) -> 0.99342105 | G7: =IF(C7="","",C7-B7) -> -25 | H7: =IF(OR(C7="",D7=""),"",C7-D7) -> -12.5
A8: 7 | B8: =SUMIFS('Base de Dados'!E2:E999,'Base de Dados'!H2:H999,">0",'Base de Dados'!H2:H999,"<="&A8,'Base de Dados'!A2:A999,"<>4.2.1 Reuniões Semanais")+(SUMIF('Base de Dados'!A2:A999,"4.2.1 Reuniões Semanais",'Base de Dados'!E2:E999)/16)*MIN(16,A8) -> 2518.75 | C8: {=IF(INDEX('Dados do Burndown'!R2:R17,A8)+6>TODAY(),"",SUMIFS('Base de Dados'!E2:E999,'Base de Dados'!G2:G999,">0",'Base de Dados'!G2:G999,"<="&A8,'Base de Dados'!F2:F999,TRUE,'Base de Dados'!A2:A999,"<>4.2.1 Reuniões Semanais")+(SUMIF('Base de Dados'!A2:A999,"4.2.1 Reuniões Semanais",'Base de Dados'!E2:E999)/16)*MIN(16,A8))} -> 2231.25 | D8: {=IF(INDEX('Dados do Burndown'!R2:R17,A8)+6>TODAY(),"",SUMIFS('Base de Dados'!D2:D999,'Base de Dados'!G2:G999,">0",'Base de Dados'!G2:G999,"<="&A8,'Base de Dados'!A2:A999,"<>4.2.1 Reuniões Semanais")+(SUMIF('Base de Dados'!A2:A999,"4.2.1 Reuniões Semanais",'Base de Dados'!E2:E999)/16)*MIN(16,A8))} -> 2200 | E8: =IF(C8="","",IFERROR(C8/B8,"")) -> 0.88585608 | F8: =IF(OR(C8="",D8=""),"",IFERROR(C8/D8,"")) -> 1.0142045 | G8: =IF(C8="","",C8-B8) -> -287.5 | H8: =IF(OR(C8="",D8=""),"",C8-D8) -> 31.25
A9: 8 | B9: =SUMIFS('Base de Dados'!E2:E999,'Base de Dados'!H2:H999,">0",'Base de Dados'!H2:H999,"<="&A9,'Base de Dados'!A2:A999,"<>4.2.1 Reuniões Semanais")+(SUMIF('Base de Dados'!A2:A999,"4.2.1 Reuniões Semanais",'Base de Dados'!E2:E999)/16)*MIN(16,A9) -> 3362.5 | C9: {=IF(INDEX('Dados do Burndown'!R2:R17,A9)+6>TODAY(),"",SUMIFS('Base de Dados'!E2:E999,'Base de Dados'!G2:G999,">0",'Base de Dados'!G2:G999,"<="&A9,'Base de Dados'!F2:F999,TRUE,'Base de Dados'!A2:A999,"<>4.2.1 Reuniões Semanais")+(SUMIF('Base de Dados'!A2:A999,"4.2.1 Reuniões Semanais",'Base de Dados'!E2:E999)/16)*MIN(16,A9))} -> 3318.75 | D9: {=IF(INDEX('Dados do Burndown'!R2:R17,A9)+6>TODAY(),"",SUMIFS('Base de Dados'!D2:D999,'Base de Dados'!G2:G999,">0",'Base de Dados'!G2:G999,"<="&A9,'Base de Dados'!A2:A999,"<>4.2.1 Reuniões Semanais")+(SUMIF('Base de Dados'!A2:A999,"4.2.1 Reuniões Semanais",'Base de Dados'!E2:E999)/16)*MIN(16,A9))} -> 2943.75 | E9: =IF(C9="","",IFERROR(C9/B9,"")) -> 0.98698885 | F9: =IF(OR(C9="",D9=""),"",IFERROR(C9/D9,"")) -> 1.1273885 | G9: =IF(C9="","",C9-B9) -> -43.75 | H9: =IF(OR(C9="",D9=""),"",C9-D9) -> 375
A10: 9 | B10: =SUMIFS('Base de Dados'!E2:E999,'Base de Dados'!H2:H999,">0",'Base de Dados'!H2:H999,"<="&A10,'Base de Dados'!A2:A999,"<>4.2.1 Reuniões Semanais")+(SUMIF('Base de Dados'!A2:A999,"4.2.1 Reuniões Semanais",'Base de Dados'!E2:E999)/16)*MIN(16,A10) -> 4006.25 | C10: {=IF(INDEX('Dados do Burndown'!R2:R17,A10)+6>TODAY(),"",SUMIFS('Base de Dados'!E2:E999,'Base de Dados'!G2:G999,">0",'Base de Dados'!G2:G999,"<="&A10,'Base de Dados'!F2:F999,TRUE,'Base de Dados'!A2:A999,"<>4.2.1 Reuniões Semanais")+(SUMIF('Base de Dados'!A2:A999,"4.2.1 Reuniões Semanais",'Base de Dados'!E2:E999)/16)*MIN(16,A10))} | D10: {=IF(INDEX('Dados do Burndown'!R2:R17,A10)+6>TODAY(),"",SUMIFS('Base de Dados'!D2:D999,'Base de Dados'!G2:G999,">0",'Base de Dados'!G2:G999,"<="&A10,'Base de Dados'!A2:A999,"<>4.2.1 Reuniões Semanais")+(SUMIF('Base de Dados'!A2:A999,"4.2.1 Reuniões Semanais",'Base de Dados'!E2:E999)/16)*MIN(16,A10))} | E10: =IF(C10="","",IFERROR(C10/B10,"")) | F10: =IF(OR(C10="",D10=""),"",IFERROR(C10/D10,"")) | G10: =IF(C10="","",C10-B10) | H10: =IF(OR(C10="",D10=""),"",C10-D10)
A11: 10 | B11: =SUMIFS('Base de Dados'!E2:E999,'Base de Dados'!H2:H999,">0",'Base de Dados'!H2:H999,"<="&A11,'Base de Dados'!A2:A999,"<>4.2.1 Reuniões Semanais")+(SUMIF('Base de Dados'!A2:A999,"4.2.1 Reuniões Semanais",'Base de Dados'!E2:E999)/16)*MIN(16,A11) -> 4725 | C11: {=IF(INDEX('Dados do Burndown'!R2:R17,A11)+6>TODAY(),"",SUMIFS('Base de Dados'!E2:E999,'Base de Dados'!G2:G999,">0",'Base de Dados'!G2:G999,"<="&A11,'Base de Dados'!F2:F999,TRUE,'Base de Dados'!A2:A999,"<>4.2.1 Reuniões Semanais")+(SUMIF('Base de Dados'!A2:A999,"4.2.1 Reuniões Semanais",'Base de Dados'!E2:E999)/16)*MIN(16,A11))} | D11: {=IF(INDEX('Dados do Burndown'!R2:R17,A11)+6>TODAY(),"",SUMIFS('Base de Dados'!D2:D999,'Base de Dados'!G2:G999,">0",'Base de Dados'!G2:G999,"<="&A11,'Base de Dados'!A2:A999,"<>4.2.1 Reuniões Semanais")+(SUMIF('Base de Dados'!A2:A999,"4.2.1 Reuniões Semanais",'Base de Dados'!E2:E999)/16)*MIN(16,A11))} | E11: =IF(C11="","",IFERROR(C11/B11,"")) | F11: =IF(OR(C11="",D11=""),"",IFERROR(C11/D11,"")) | G11: =IF(C11="","",C11-B11) | H11: =IF(OR(C11="",D11=""),"",C11-D11)
A12: 11 | B12: =SUMIFS('Base de Dados'!E2:E999,'Base de Dados'!H2:H999,">0",'Base de Dados'!H2:H999,"<="&A12,'Base de Dados'!A2:A999,"<>4.2.1 Reuniões Semanais")+(SUMIF('Base de Dados'!A2:A999,"4.2.1 Reuniões Semanais",'Base de Dados'!E2:E999)/16)*MIN(16,A12) -> 4943.75 | C12: {=IF(INDEX('Dados do Burndown'!R2:R17,A12)+6>TODAY(),"",SUMIFS('Base de Dados'!E2:E999,'Base de Dados'!G2:G999,">0",'Base de Dados'!G2:G999,"<="&A12,'Base de Dados'!F2:F999,TRUE,'Base de Dados'!A2:A999,"<>4.2.1 Reuniões Semanais")+(SUMIF('Base de Dados'!A2:A999,"4.2.1 Reuniões Semanais",'Base de Dados'!E2:E999)/16)*MIN(16,A12))} | D12: {=IF(INDEX('Dados do Burndown'!R2:R17,A12)+6>TODAY(),"",SUMIFS('Base de Dados'!D2:D999,'Base de Dados'!G2:G999,">0",'Base de Dados'!G2:G999,"<="&A12,'Base de Dados'!A2:A999,"<>4.2.1 Reuniões Semanais")+(SUMIF('Base de Dados'!A2:A999,"4.2.1 Reuniões Semanais",'Base de Dados'!E2:E999)/16)*MIN(16,A12))} | E12: =IF(C12="","",IFERROR(C12/B12,"")) | F12: =IF(OR(C12="",D12=""),"",IFERROR(C12/D12,"")) | G12: =IF(C12="","",C12-B12) | H12: =IF(OR(C12="",D12=""),"",C12-D12)
A13: 12 | B13: =SUMIFS('Base de Dados'!E2:E999,'Base de Dados'!H2:H999,">0",'Base de Dados'!H2:H999,"<="&A13,'Base de Dados'!A2:A999,"<>4.2.1 Reuniões Semanais")+(SUMIF('Base de Dados'!A2:A999,"4.2.1 Reuniões Semanais",'Base de Dados'!E2:E999)/16)*MIN(16,A13) -> 5162.5 | C13: {=IF(INDEX('Dados do Burndown'!R2:R17,A13)+6>TODAY(),"",SUMIFS('Base de Dados'!E2:E999,'Base de Dados'!G2:G999,">0",'Base de Dados'!G2:G999,"<="&A13,'Base de Dados'!F2:F999,TRUE,'Base de Dados'!A2:A999,"<>4.2.1 Reuniões Semanais")+(SUMIF('Base de Dados'!A2:A999,"4.2.1 Reuniões Semanais",'Base de Dados'!E2:E999)/16)*MIN(16,A13))} | D13: {=IF(INDEX('Dados do Burndown'!R2:R17,A13)+6>TODAY(),"",SUMIFS('Base de Dados'!D2:D999,'Base de Dados'!G2:G999,">0",'Base de Dados'!G2:G999,"<="&A13,'Base de Dados'!A2:A999,"<>4.2.1 Reuniões Semanais")+(SUMIF('Base de Dados'!A2:A999,"4.2.1 Reuniões Semanais",'Base de Dados'!E2:E999)/16)*MIN(16,A13))} | E13: =IF(C13="","",IFERROR(C13/B13,"")) | F13: =IF(OR(C13="",D13=""),"",IFERROR(C13/D13,"")) | G13: =IF(C13="","",C13-B13) | H13: =IF(OR(C13="",D13=""),"",C13-D13)
A14: 13 | B14: =SUMIFS('Base de Dados'!E2:E999,'Base de Dados'!H2:H999,">0",'Base de Dados'!H2:H999,"<="&A14,'Base de Dados'!A2:A999,"<>4.2.1 Reuniões Semanais")+(SUMIF('Base de Dados'!A2:A999,"4.2.1 Reuniões Semanais",'Base de Dados'!E2:E999)/16)*MIN(16,A14) -> 5381.25 | C14: {=IF(INDEX('Dados do Burndown'!R2:R17,A14)+6>TODAY(),"",SUMIFS('Base de Dados'!E2:E999,'Base de Dados'!G2:G999,">0",'Base de Dados'!G2:G999,"<="&A14,'Base de Dados'!F2:F999,TRUE,'Base de Dados'!A2:A999,"<>4.2.1 Reuniões Semanais")+(SUMIF('Base de Dados'!A2:A999,"4.2.1 Reuniões Semanais",'Base de Dados'!E2:E999)/16)*MIN(16,A14))} | D14: {=IF(INDEX('Dados do Burndown'!R2:R17,A14)+6>TODAY(),"",SUMIFS('Base de Dados'!D2:D999,'Base de Dados'!G2:G999,">0",'Base de Dados'!G2:G999,"<="&A14,'Base de Dados'!A2:A999,"<>4.2.1 Reuniões Semanais")+(SUMIF('Base de Dados'!A2:A999,"4.2.1 Reuniões Semanais",'Base de Dados'!E2:E999)/16)*MIN(16,A14))} | E14: =IF(C14="","",IFERROR(C14/B14,"")) | F14: =IF(OR(C14="",D14=""),"",IFERROR(C14/D14,"")) | G14: =IF(C14="","",C14-B14) | H14: =IF(OR(C14="",D14=""),"",C14-D14)
A15: 14 | B15: =SUMIFS('Base de Dados'!E2:E999,'Base de Dados'!H2:H999,">0",'Base de Dados'!H2:H999,"<="&A15,'Base de Dados'!A2:A999,"<>4.2.1 Reuniões Semanais")+(SUMIF('Base de Dados'!A2:A999,"4.2.1 Reuniões Semanais",'Base de Dados'!E2:E999)/16)*MIN(16,A15) -> 5600 | C15: {=IF(INDEX('Dados do Burndown'!R2:R17,A15)+6>TODAY(),"",SUMIFS('Base de Dados'!E2:E999,'Base de Dados'!G2:G999,">0",'Base de Dados'!G2:G999,"<="&A15,'Base de Dados'!F2:F999,TRUE,'Base de Dados'!A2:A999,"<>4.2.1 Reuniões Semanais")+(SUMIF('Base de Dados'!A2:A999,"4.2.1 Reuniões Semanais",'Base de Dados'!E2:E999)/16)*MIN(16,A15))} | D15: {=IF(INDEX('Dados do Burndown'!R2:R17,A15)+6>TODAY(),"",SUMIFS('Base de Dados'!D2:D999,'Base de Dados'!G2:G999,">0",'Base de Dados'!G2:G999,"<="&A15,'Base de Dados'!A2:A999,"<>4.2.1 Reuniões Semanais")+(SUMIF('Base de Dados'!A2:A999,"4.2.1 Reuniões Semanais",'Base de Dados'!E2:E999)/16)*MIN(16,A15))} | E15: =IF(C15="","",IFERROR(C15/B15,"")) | F15: =IF(OR(C15="",D15=""),"",IFERROR(C15/D15,"")) | G15: =IF(C15="","",C15-B15) | H15: =IF(OR(C15="",D15=""),"",C15-D15)
A16: 15 | B16: =SUMIFS('Base de Dados'!E2:E999,'Base de Dados'!H2:H999,">0",'Base de Dados'!H2:H999,"<="&A16,'Base de Dados'!A2:A999,"<>4.2.1 Reuniões Semanais")+(SUMIF('Base de Dados'!A2:A999,"4.2.1 Reuniões Semanais",'Base de Dados'!E2:E999)/16)*MIN(16,A16) -> 6081.25 | C16: {=IF(INDEX('Dados do Burndown'!R2:R17,A16)+6>TODAY(),"",SUMIFS('Base de Dados'!E2:E999,'Base de Dados'!G2:G999,">0",'Base de Dados'!G2:G999,"<="&A16,'Base de Dados'!F2:F999,TRUE,'Base de Dados'!A2:A999,"<>4.2.1 Reuniões Semanais")+(SUMIF('Base de Dados'!A2:A999,"4.2.1 Reuniões Semanais",'Base de Dados'!E2:E999)/16)*MIN(16,A16))} | D16: {=IF(INDEX('Dados do Burndown'!R2:R17,A16)+6>TODAY(),"",SUMIFS('Base de Dados'!D2:D999,'Base de Dados'!G2:G999,">0",'Base de Dados'!G2:G999,"<="&A16,'Base de Dados'!A2:A999,"<>4.2.1 Reuniões Semanais")+(SUMIF('Base de Dados'!A2:A999,"4.2.1 Reuniões Semanais",'Base de Dados'!E2:E999)/16)*MIN(16,A16))} | E16: =IF(C16="","",IFERROR(C16/B16,"")) | F16: =IF(OR(C16="",D16=""),"",IFERROR(C16/D16,"")) | G16: =IF(C16="","",C16-B16) | H16: =IF(OR(C16="",D16=""),"",C16-D16)
A17: 16 | B17: =SUMIFS('Base de Dados'!E2:E999,'Base de Dados'!H2:H999,">0",'Base de Dados'!H2:H999,"<="&A17,'Base de Dados'!A2:A999,"<>4.2.1 Reuniões Semanais")+(SUMIF('Base de Dados'!A2:A999,"4.2.1 Reuniões Semanais",'Base de Dados'!E2:E999)/16)*MIN(16,A17) -> 6343.75 | C17: {=IF(INDEX('Dados do Burndown'!R2:R17,A17)+6>TODAY(),"",SUMIFS('Base de Dados'!E2:E999,'Base de Dados'!G2:G999,">0",'Base de Dados'!G2:G999,"<="&A17,'Base de Dados'!F2:F999,TRUE,'Base de Dados'!A2:A999,"<>4.2.1 Reuniões Semanais")+(SUMIF('Base de Dados'!A2:A999,"4.2.1 Reuniões Semanais",'Base de Dados'!E2:E999)/16)*MIN(16,A17))} | D17: {=IF(INDEX('Dados do Burndown'!R2:R17,A17)+6>TODAY(),"",SUMIFS('Base de Dados'!D2:D999,'Base de Dados'!G2:G999,">0",'Base de Dados'!G2:G999,"<="&A17,'Base de Dados'!A2:A999,"<>4.2.1 Reuniões Semanais")+(SUMIF('Base de Dados'!A2:A999,"4.2.1 Reuniões Semanais",'Base de Dados'!E2:E999)/16)*MIN(16,A17))} | E17: =IF(C17="","",IFERROR(C17/B17,"")) | F17: =IF(OR(C17="",D17=""),"",IFERROR(C17/D17,"")) | G17: =IF(C17="","",C17-B17) | H17: =IF(OR(C17="",D17=""),"",C17-D17)
A20: Concluída
A21: Em andamento
A22: Futura
A24: Reuniões: 1 por iteração

Sheet Burndown por Iteração
A1: Burndown por iteração
A2: Planejamento: Base de Dados, coluna H. Só tarefas desse escopo baixam o saldo; reuniões incluídas (esforço total ÷ 16).
A3: Iteração | B3: Esforço do escopo | C3: Restante no início | D3: Restante no fim | E3: Situação | F3: Datas pendentes
A4: 1 | B4: =SUMIF('Dados do Burndown'!E2:E780,A4,'Dados do Burndown'!B2:B780) -> 24.5 | C4: =MAX(0,B4-SUMIFS('Dados do Burndown'!B2:B780,'Dados do Burndown'!E2:E780,A4,'Dados do Burndown'!C2:C780,TRUE,'Dados do Burndown'!D2:D780,">0",'Dados do Burndown'!D2:D780,"<="&'Dados do Burndown'!R2-1)-SUMIFS('Dados do Burndown'!B2:B780,'Dados do Burndown'!E2:E780,A4,'Dados do Burndown'!C2:C780,TRUE,'Dados do Burndown'!D2:D780,"",'Dados do Burndown'!F2:F780,">0",'Dados do Burndown'!F2:F780,"<"&A4)) -> 24.5 | D4: =IF('Dados do Burndown'!R2+6>TODAY(),"",MAX(0,B4-SUMIFS('Dados do Burndown'!B2:B780,'Dados do Burndown'!E2:E780,A4,'Dados do Burndown'!C2:C780,TRUE,'Dados do Burndown'!D2:D780,">0",'Dados do Burndown'!D2:D780,"<="&'Dados do Burndown'!R2+6)-SUMIFS('Dados do Burndown'!B2:B780,'Dados do Burndown'!E2:E780,A4,'Dados do Burndown'!C2:C780,TRUE,'Dados do Burndown'!D2:D780,"",'Dados do Burndown'!F2:F780,">0",'Dados do Burndown'!F2:F780,"<="&A4))) -> 0 | E4: =IF('Dados do Burndown'!R2>TODAY(),"Futura",IF(F4>0,"Preencher datas de conclusão",IF('Dados do Burndown'!R2+6>TODAY(),"Em andamento",IF(OR(D4>0,COUNTIFS('Dados do Burndown'!E2:E780,A4,'Dados do Burndown'!C2:C780,FALSE)>0),"Há esforço pendente","Escopo concluído")))) -> Escopo concluído | F4: =COUNTIFS('Dados do Burndown'!E2:E780,A4,'Dados do Burndown'!B2:B780,">0",'Dados do Burndown'!C2:C780,TRUE,'Dados do Burndown'!D2:D780,"") -> 0
A5: 2 | B5: =SUMIF('Dados do Burndown'!E2:E780,A5,'Dados do Burndown'!B2:B780) -> 23.5 | C5: =MAX(0,B5-SUMIFS('Dados do Burndown'!B2:B780,'Dados do Burndown'!E2:E780,A5,'Dados do Burndown'!C2:C780,TRUE,'Dados do Burndown'!D2:D780,">0",'Dados do Burndown'!D2:D780,"<="&'Dados do Burndown'!R3-1)-SUMIFS('Dados do Burndown'!B2:B780,'Dados do Burndown'!E2:E780,A5,'Dados do Burndown'!C2:C780,TRUE,'Dados do Burndown'!D2:D780,"",'Dados do Burndown'!F2:F780,">0",'Dados do Burndown'!F2:F780,"<"&A5)) -> 23.5 | D5: =IF('Dados do Burndown'!R3+6>TODAY(),"",MAX(0,B5-SUMIFS('Dados do Burndown'!B2:B780,'Dados do Burndown'!E2:E780,A5,'Dados do Burndown'!C2:C780,TRUE,'Dados do Burndown'!D2:D780,">0",'Dados do Burndown'!D2:D780,"<="&'Dados do Burndown'!R3+6)-SUMIFS('Dados do Burndown'!B2:B780,'Dados do Burndown'!E2:E780,A5,'Dados do Burndown'!C2:C780,TRUE,'Dados do Burndown'!D2:D780,"",'Dados do Burndown'!F2:F780,">0",'Dados do Burndown'!F2:F780,"<="&A5))) -> 6 | E5: =IF('Dados do Burndown'!R3>TODAY(),"Futura",IF(F5>0,"Preencher datas de conclusão",IF('Dados do Burndown'!R3+6>TODAY(),"Em andamento",IF(OR(D5>0,COUNTIFS('Dados do Burndown'!E2:E780,A5,'Dados do Burndown'!C2:C780,FALSE)>0),"Há esforço pendente","Escopo concluído")))) -> Há esforço pendente | F5: =COUNTIFS('Dados do Burndown'!E2:E780,A5,'Dados do Burndown'!B2:B780,">0",'Dados do Burndown'!C2:C780,TRUE,'Dados do Burndown'!D2:D780,"") -> 0
A6: 3 | B6: =SUMIF('Dados do Burndown'!E2:E780,A6,'Dados do Burndown'!B2:B780) -> 25.5 | C6: =MAX(0,B6-SUMIFS('Dados do Burndown'!B2:B780,'Dados do Burndown'!E2:E780,A6,'Dados do Burndown'!C2:C780,TRUE,'Dados do Burndown'!D2:D780,">0",'Dados do Burndown'!D2:D780,"<="&'Dados do Burndown'!R4-1)-SUMIFS('Dados do Burndown'!B2:B780,'Dados do Burndown'!E2:E780,A6,'Dados do Burndown'!C2:C780,TRUE,'Dados do Burndown'!D2:D780,"",'Dados do Burndown'!F2:F780,">0",'Dados do Burndown'!F2:F780,"<"&A6)) -> 25.5 | D6: =IF('Dados do Burndown'!R4+6>TODAY(),"",MAX(0,B6-SUMIFS('Dados do Burndown'!B2:B780,'Dados do Burndown'!E2:E780,A6,'Dados do Burndown'!C2:C780,TRUE,'Dados do Burndown'!D2:D780,">0",'Dados do Burndown'!D2:D780,"<="&'Dados do Burndown'!R4+6)-SUMIFS('Dados do Burndown'!B2:B780,'Dados do Burndown'!E2:E780,A6,'Dados do Burndown'!C2:C780,TRUE,'Dados do Burndown'!D2:D780,"",'Dados do Burndown'!F2:F780,">0",'Dados do Burndown'!F2:F780,"<="&A6))) -> 0 | E6: =IF('Dados do Burndown'!R4>TODAY(),"Futura",IF(F6>0,"Preencher datas de conclusão",IF('Dados do Burndown'!R4+6>TODAY(),"Em andamento",IF(OR(D6>0,COUNTIFS('Dados do Burndown'!E2:E780,A6,'Dados do Burndown'!C2:C780,FALSE)>0),"Há esforço pendente","Escopo concluído")))) -> Escopo concluído | F6: =COUNTIFS('Dados do Burndown'!E2:E780,A6,'Dados do Burndown'!B2:B780,">0",'Dados do Burndown'!C2:C780,TRUE,'Dados do Burndown'!D2:D780,"") -> 0
A7: 4 | B7: =SUMIF('Dados do Burndown'!E2:E780,A7,'Dados do Burndown'!B2:B780) -> 20.5 | C7: =MAX(0,B7-SUMIFS('Dados do Burndown'!B2:B780,'Dados do Burndown'!E2:E780,A7,'Dados do Burndown'!C2:C780,TRUE,'Dados do Burndown'!D2:D780,">0",'Dados do Burndown'!D2:D780,"<="&'Dados do Burndown'!R5-1)-SUMIFS('Dados do Burndown'!B2:B780,'Dados do Burndown'!E2:E780,A7,'Dados do Burndown'!C2:C780,TRUE,'Dados do Burndown'!D2:D780,"",'Dados do Burndown'!F2:F780,">0",'Dados do Burndown'!F2:F780,"<"&A7)) -> 20.5 | D7: =IF('Dados do Burndown'!R5+6>TODAY(),"",MAX(0,B7-SUMIFS('Dados do Burndown'!B2:B780,'Dados do Burndown'!E2:E780,A7,'Dados do Burndown'!C2:C780,TRUE,'Dados do Burndown'!D2:D780,">0",'Dados do Burndown'!D2:D780,"<="&'Dados do Burndown'!R5+6)-SUMIFS('Dados do Burndown'!B2:B780,'Dados do Burndown'!E2:E780,A7,'Dados do Burndown'!C2:C780,TRUE,'Dados do Burndown'!D2:D780,"",'Dados do Burndown'!F2:F780,">0",'Dados do Burndown'!F2:F780,"<="&A7))) -> 0 | E7: =IF('Dados do Burndown'!R5>TODAY(),"Futura",IF(F7>0,"Preencher datas de conclusão",IF('Dados do Burndown'!R5+6>TODAY(),"Em andamento",IF(OR(D7>0,COUNTIFS('Dados do Burndown'!E2:E780,A7,'Dados do Burndown'!C2:C780,FALSE)>0),"Há esforço pendente","Escopo concluído")))) -> Escopo concluído | F7: =COUNTIFS('Dados do Burndown'!E2:E780,A7,'Dados do Burndown'!B2:B780,">0",'Dados do Burndown'!C2:C780,TRUE,'Dados do Burndown'!D2:D780,"") -> 0
A8: 5 | B8: =SUMIF('Dados do Burndown'!E2:E780,A8,'Dados do Burndown'!B2:B780) -> 38 | C8: =MAX(0,B8-SUMIFS('Dados do Burndown'!B2:B780,'Dados do Burndown'!E2:E780,A8,'Dados do Burndown'!C2:C780,TRUE,'Dados do Burndown'!D2:D780,">0",'Dados do Burndown'!D2:D780,"<="&'Dados do Burndown'!R6-1)-SUMIFS('Dados do Burndown'!B2:B780,'Dados do Burndown'!E2:E780,A8,'Dados do Burndown'!C2:C780,TRUE,'Dados do Burndown'!D2:D780,"",'Dados do Burndown'!F2:F780,">0",'Dados do Burndown'!F2:F780,"<"&A8)) -> 38 | D8: =IF('Dados do Burndown'!R6+6>TODAY(),"",MAX(0,B8-SUMIFS('Dados do Burndown'!B2:B780,'Dados do Burndown'!E2:E780,A8,'Dados do Burndown'!C2:C780,TRUE,'Dados do Burndown'!D2:D780,">0",'Dados do Burndown'!D2:D780,"<="&'Dados do Burndown'!R6+6)-SUMIFS('Dados do Burndown'!B2:B780,'Dados do Burndown'!E2:E780,A8,'Dados do Burndown'!C2:C780,TRUE,'Dados do Burndown'!D2:D780,"",'Dados do Burndown'!F2:F780,">0",'Dados do Burndown'!F2:F780,"<="&A8))) -> 5 | E8: =IF('Dados do Burndown'!R6>TODAY(),"Futura",IF(F8>0,"Preencher datas de conclusão",IF('Dados do Burndown'!R6+6>TODAY(),"Em andamento",IF(OR(D8>0,COUNTIFS('Dados do Burndown'!E2:E780,A8,'Dados do Burndown'!C2:C780,FALSE)>0),"Há esforço pendente","Escopo concluído")))) -> Há esforço pendente | F8: =COUNTIFS('Dados do Burndown'!E2:E780,A8,'Dados do Burndown'!B2:B780,">0",'Dados do Burndown'!C2:C780,TRUE,'Dados do Burndown'!D2:D780,"") -> 0
A9: 6 | B9: =SUMIF('Dados do Burndown'!E2:E780,A9,'Dados do Burndown'!B2:B780) -> 21 | C9: =MAX(0,B9-SUMIFS('Dados do Burndown'!B2:B780,'Dados do Burndown'!E2:E780,A9,'Dados do Burndown'!C2:C780,TRUE,'Dados do Burndown'!D2:D780,">0",'Dados do Burndown'!D2:D780,"<="&'Dados do Burndown'!R7-1)-SUMIFS('Dados do Burndown'!B2:B780,'Dados do Burndown'!E2:E780,A9,'Dados do Burndown'!C2:C780,TRUE,'Dados do Burndown'!D2:D780,"",'Dados do Burndown'!F2:F780,">0",'Dados do Burndown'!F2:F780,"<"&A9)) -> 21 | D9: =IF('Dados do Burndown'!R7+6>TODAY(),"",MAX(0,B9-SUMIFS('Dados do Burndown'!B2:B780,'Dados do Burndown'!E2:E780,A9,'Dados do Burndown'!C2:C780,TRUE,'Dados do Burndown'!D2:D780,">0",'Dados do Burndown'!D2:D780,"<="&'Dados do Burndown'!R7+6)-SUMIFS('Dados do Burndown'!B2:B780,'Dados do Burndown'!E2:E780,A9,'Dados do Burndown'!C2:C780,TRUE,'Dados do Burndown'!D2:D780,"",'Dados do Burndown'!F2:F780,">0",'Dados do Burndown'!F2:F780,"<="&A9))) -> 0 | E9: =IF('Dados do Burndown'!R7>TODAY(),"Futura",IF(F9>0,"Preencher datas de conclusão",IF('Dados do Burndown'!R7+6>TODAY(),"Em andamento",IF(OR(D9>0,COUNTIFS('Dados do Burndown'!E2:E780,A9,'Dados do Burndown'!C2:C780,FALSE)>0),"Há esforço pendente","Escopo concluído")))) -> Escopo concluído | F9: =COUNTIFS('Dados do Burndown'!E2:E780,A9,'Dados do Burndown'!B2:B780,">0",'Dados do Burndown'!C2:C780,TRUE,'Dados do Burndown'!D2:D780,"") -> 0
A10: 7 | B10: =SUMIF('Dados do Burndown'!E2:E780,A10,'Dados do Burndown'!B2:B780) -> 48.5 | C10: =MAX(0,B10-SUMIFS('Dados do Burndown'!B2:B780,'Dados do Burndown'!E2:E780,A10,'Dados do Burndown'!C2:C780,TRUE,'Dados do Burndown'!D2:D780,">0",'Dados do Burndown'!D2:D780,"<="&'Dados do Burndown'!R8-1)-SUMIFS('Dados do Burndown'!B2:B780,'Dados do Burndown'!E2:E780,A10,'Dados do Burndown'!C2:C780,TRUE,'Dados do Burndown'!D2:D780,"",'Dados do Burndown'!F2:F780,">0",'Dados do Burndown'!F2:F780,"<"&A10)) -> 45.5 | D10: =IF('Dados do Burndown'!R8+6>TODAY(),"",MAX(0,B10-SUMIFS('Dados do Burndown'!B2:B780,'Dados do Burndown'!E2:E780,A10,'Dados do Burndown'!C2:C780,TRUE,'Dados do Burndown'!D2:D780,">0",'Dados do Burndown'!D2:D780,"<="&'Dados do Burndown'!R8+6)-SUMIFS('Dados do Burndown'!B2:B780,'Dados do Burndown'!E2:E780,A10,'Dados do Burndown'!C2:C780,TRUE,'Dados do Burndown'!D2:D780,"",'Dados do Burndown'!F2:F780,">0",'Dados do Burndown'!F2:F780,"<="&A10))) -> 18 | E10: =IF('Dados do Burndown'!R8>TODAY(),"Futura",IF(F10>0,"Preencher datas de conclusão",IF('Dados do Burndown'!R8+6>TODAY(),"Em andamento",IF(OR(D10>0,COUNTIFS('Dados do Burndown'!E2:E780,A10,'Dados do Burndown'!C2:C780,FALSE)>0),"Há esforço pendente","Escopo concluído")))) -> Há esforço pendente | F10: =COUNTIFS('Dados do Burndown'!E2:E780,A10,'Dados do Burndown'!B2:B780,">0",'Dados do Burndown'!C2:C780,TRUE,'Dados do Burndown'!D2:D780,"") -> 0
A11: 8 | B11: =SUMIF('Dados do Burndown'!E2:E780,A11,'Dados do Burndown'!B2:B780) -> 67.5 | C11: =MAX(0,B11-SUMIFS('Dados do Burndown'!B2:B780,'Dados do Burndown'!E2:E780,A11,'Dados do Burndown'!C2:C780,TRUE,'Dados do Burndown'!D2:D780,">0",'Dados do Burndown'!D2:D780,"<="&'Dados do Burndown'!R9-1)-SUMIFS('Dados do Burndown'!B2:B780,'Dados do Burndown'!E2:E780,A11,'Dados do Burndown'!C2:C780,TRUE,'Dados do Burndown'!D2:D780,"",'Dados do Burndown'!F2:F780,">0",'Dados do Burndown'!F2:F780,"<"&A11)) -> 67.5 | D11: =IF('Dados do Burndown'!R9+6>TODAY(),"",MAX(0,B11-SUMIFS('Dados do Burndown'!B2:B780,'Dados do Burndown'!E2:E780,A11,'Dados do Burndown'!C2:C780,TRUE,'Dados do Burndown'!D2:D780,">0",'Dados do Burndown'!D2:D780,"<="&'Dados do Burndown'!R9+6)-SUMIFS('Dados do Burndown'!B2:B780,'Dados do Burndown'!E2:E780,A11,'Dados do Burndown'!C2:C780,TRUE,'Dados do Burndown'!D2:D780,"",'Dados do Burndown'!F2:F780,">0",'Dados do Burndown'!F2:F780,"<="&A11))) -> 22 | E11: =IF('Dados do Burndown'!R9>TODAY(),"Futura",IF(F11>0,"Preencher datas de conclusão",IF('Dados do Burndown'!R9+6>TODAY(),"Em andamento",IF(OR(D11>0,COUNTIFS('Dados do Burndown'!E2:E780,A11,'Dados do Burndown'!C2:C780,FALSE)>0),"Há esforço pendente","Escopo concluído")))) -> Há esforço pendente | F11: =COUNTIFS('Dados do Burndown'!E2:E780,A11,'Dados do Burndown'!B2:B780,">0",'Dados do Burndown'!C2:C780,TRUE,'Dados do Burndown'!D2:D780,"") -> 0
A12: 9 | B12: =SUMIF('Dados do Burndown'!E2:E780,A12,'Dados do Burndown'!B2:B780) -> 51.5 | C12: =MAX(0,B12-SUMIFS('Dados do Burndown'!B2:B780,'Dados do Burndown'!E2:E780,A12,'Dados do Burndown'!C2:C780,TRUE,'Dados do Burndown'!D2:D780,">0",'Dados do Burndown'!D2:D780,"<="&'Dados do Burndown'!R10-1)-SUMIFS('Dados do Burndown'!B2:B780,'Dados do Burndown'!E2:E780,A12,'Dados do Burndown'!C2:C780,TRUE,'Dados do Burndown'!D2:D780,"",'Dados do Burndown'!F2:F780,">0",'Dados do Burndown'!F2:F780,"<"&A12)) -> 28 | D12: =IF('Dados do Burndown'!R10+6>TODAY(),"",MAX(0,B12-SUMIFS('Dados do Burndown'!B2:B780,'Dados do Burndown'!E2:E780,A12,'Dados do Burndown'!C2:C780,TRUE,'Dados do Burndown'!D2:D780,">0",'Dados do Burndown'!D2:D780,"<="&'Dados do Burndown'!R10+6)-SUMIFS('Dados do Burndown'!B2:B780,'Dados do Burndown'!E2:E780,A12,'Dados do Burndown'!C2:C780,TRUE,'Dados do Burndown'!D2:D780,"",'Dados do Burndown'!F2:F780,">0",'Dados do Burndown'!F2:F780,"<="&A12))) | E12: =IF('Dados do Burndown'!R10>TODAY(),"Futura",IF(F12>0,"Preencher datas de conclusão",IF('Dados do Burndown'!R10+6>TODAY(),"Em andamento",IF(OR(D12>0,COUNTIFS('Dados do Burndown'!E2:E780,A12,'Dados do Burndown'!C2:C780,FALSE)>0),"Há esforço pendente","Escopo concluído")))) -> Futura | F12: =COUNTIFS('Dados do Burndown'!E2:E780,A12,'Dados do Burndown'!B2:B780,">0",'Dados do Burndown'!C2:C780,TRUE,'Dados do Burndown'!D2:D780,"") -> 0
A13: 10 | B13: =SUMIF('Dados do Burndown'!E2:E780,A13,'Dados do Burndown'!B2:B780) -> 57.5 | C13: =MAX(0,B13-SUMIFS('Dados do Burndown'!B2:B780,'Dados do Burndown'!E2:E780,A13,'Dados do Burndown'!C2:C780,TRUE,'Dados do Burndown'!D2:D780,">0",'Dados do Burndown'!D2:D780,"<="&'Dados do Burndown'!R11-1)-SUMIFS('Dados do Burndown'!B2:B780,'Dados do Burndown'!E2:E780,A13,'Dados do Burndown'!C2:C780,TRUE,'Dados do Burndown'!D2:D780,"",'Dados do Burndown'!F2:F780,">0",'Dados do Burndown'!F2:F780,"<"&A13)) -> 57.5 | D13: =IF('Dados do Burndown'!R11+6>TODAY(),"",MAX(0,B13-SUMIFS('Dados do Burndown'!B2:B780,'Dados do Burndown'!E2:E780,A13,'Dados do Burndown'!C2:C780,TRUE,'Dados do Burndown'!D2:D780,">0",'Dados do Burndown'!D2:D780,"<="&'Dados do Burndown'!R11+6)-SUMIFS('Dados do Burndown'!B2:B780,'Dados do Burndown'!E2:E780,A13,'Dados do Burndown'!C2:C780,TRUE,'Dados do Burndown'!D2:D780,"",'Dados do Burndown'!F2:F780,">0",'Dados do Burndown'!F2:F780,"<="&A13))) | E13: =IF('Dados do Burndown'!R11>TODAY(),"Futura",IF(F13>0,"Preencher datas de conclusão",IF('Dados do Burndown'!R11+6>TODAY(),"Em andamento",IF(OR(D13>0,COUNTIFS('Dados do Burndown'!E2:E780,A13,'Dados do Burndown'!C2:C780,FALSE)>0),"Há esforço pendente","Escopo concluído")))) -> Futura | F13: =COUNTIFS('Dados do Burndown'!E2:E780,A13,'Dados do Burndown'!B2:B780,">0",'Dados do Burndown'!C2:C780,TRUE,'Dados do Burndown'!D2:D780,"") -> 0
A14: 11 | B14: =SUMIF('Dados do Burndown'!E2:E780,A14,'Dados do Burndown'!B2:B780) -> 17.5 | C14: =MAX(0,B14-SUMIFS('Dados do Burndown'!B2:B780,'Dados do Burndown'!E2:E780,A14,'Dados do Burndown'!C2:C780,TRUE,'Dados do Burndown'!D2:D780,">0",'Dados do Burndown'!D2:D780,"<="&'Dados do Burndown'!R12-1)-SUMIFS('Dados do Burndown'!B2:B780,'Dados do Burndown'!E2:E780,A14,'Dados do Burndown'!C2:C780,TRUE,'Dados do Burndown'!D2:D780,"",'Dados do Burndown'!F2:F780,">0",'Dados do Burndown'!F2:F780,"<"&A14)) -> 17.5 | D14: =IF('Dados do Burndown'!R12+6>TODAY(),"",MAX(0,B14-SUMIFS('Dados do Burndown'!B2:B780,'Dados do Burndown'!E2:E780,A14,'Dados do Burndown'!C2:C780,TRUE,'Dados do Burndown'!D2:D780,">0",'Dados do Burndown'!D2:D780,"<="&'Dados do Burndown'!R12+6)-SUMIFS('Dados do Burndown'!B2:B780,'Dados do Burndown'!E2:E780,A14,'Dados do Burndown'!C2:C780,TRUE,'Dados do Burndown'!D2:D780,"",'Dados do Burndown'!F2:F780,">0",'Dados do Burndown'!F2:F780,"<="&A14))) | E14: =IF('Dados do Burndown'!R12>TODAY(),"Futura",IF(F14>0,"Preencher datas de conclusão",IF('Dados do Burndown'!R12+6>TODAY(),"Em andamento",IF(OR(D14>0,COUNTIFS('Dados do Burndown'!E2:E780,A14,'Dados do Burndown'!C2:C780,FALSE)>0),"Há esforço pendente","Escopo concluído")))) -> Futura | F14: =COUNTIFS('Dados do Burndown'!E2:E780,A14,'Dados do Burndown'!B2:B780,">0",'Dados do Burndown'!C2:C780,TRUE,'Dados do Burndown'!D2:D780,"") -> 0
A15: 12 | B15: =SUMIF('Dados do Burndown'!E2:E780,A15,'Dados do Burndown'!B2:B780) -> 17.5 | C15: =MAX(0,B15-SUMIFS('Dados do Burndown'!B2:B780,'Dados do Burndown'!E2:E780,A15,'Dados do Burndown'!C2:C780,TRUE,'Dados do Burndown'!D2:D780,">0",'Dados do Burndown'!D2:D780,"<="&'Dados do Burndown'!R13-1)-SUMIFS('Dados do Burndown'!B2:B780,'Dados do Burndown'!E2:E780,A15,'Dados do Burndown'!C2:C780,TRUE,'Dados do Burndown'!D2:D780,"",'Dados do Burndown'!F2:F780,">0",'Dados do Burndown'!F2:F780,"<"&A15)) -> 17.5 | D15: =IF('Dados do Burndown'!R13+6>TODAY(),"",MAX(0,B15-SUMIFS('Dados do Burndown'!B2:B780,'Dados do Burndown'!E2:E780,A15,'Dados do Burndown'!C2:C780,TRUE,'Dados do Burndown'!D2:D780,">0",'Dados do Burndown'!D2:D780,"<="&'Dados do Burndown'!R13+6)-SUMIFS('Dados do Burndown'!B2:B780,'Dados do Burndown'!E2:E780,A15,'Dados do Burndown'!C2:C780,TRUE,'Dados do Burndown'!D2:D780,"",'Dados do Burndown'!F2:F780,">0",'Dados do Burndown'!F2:F780,"<="&A15))) | E15: =IF('Dados do Burndown'!R13>TODAY(),"Futura",IF(F15>0,"Preencher datas de conclusão",IF('Dados do Burndown'!R13+6>TODAY(),"Em andamento",IF(OR(D15>0,COUNTIFS('Dados do Burndown'!E2:E780,A15,'Dados do Burndown'!C2:C780,FALSE)>0),"Há esforço pendente","Escopo concluído")))) -> Futura | F15: =COUNTIFS('Dados do Burndown'!E2:E780,A15,'Dados do Burndown'!B2:B780,">0",'Dados do Burndown'!C2:C780,TRUE,'Dados do Burndown'!D2:D780,"") -> 0
A16: 13 | B16: =SUMIF('Dados do Burndown'!E2:E780,A16,'Dados do Burndown'!B2:B780) -> 17.5 | C16: =MAX(0,B16-SUMIFS('Dados do Burndown'!B2:B780,'Dados do Burndown'!E2:E780,A16,'Dados do Burndown'!C2:C780,TRUE,'Dados do Burndown'!D2:D780,">0",'Dados do Burndown'!D2:D780,"<="&'Dados do Burndown'!R14-1)-SUMIFS('Dados do Burndown'!B2:B780,'Dados do Burndown'!E2:E780,A16,'Dados do Burndown'!C2:C780,TRUE,'Dados do Burndown'!D2:D780,"",'Dados do Burndown'!F2:F780,">0",'Dados do Burndown'!F2:F780,"<"&A16)) -> 17.5 | D16: =IF('Dados do Burndown'!R14+6>TODAY(),"",MAX(0,B16-SUMIFS('Dados do Burndown'!B2:B780,'Dados do Burndown'!E2:E780,A16,'Dados do Burndown'!C2:C780,TRUE,'Dados do Burndown'!D2:D780,">0",'Dados do Burndown'!D2:D780,"<="&'Dados do Burndown'!R14+6)-SUMIFS('Dados do Burndown'!B2:B780,'Dados do Burndown'!E2:E780,A16,'Dados do Burndown'!C2:C780,TRUE,'Dados do Burndown'!D2:D780,"",'Dados do Burndown'!F2:F780,">0",'Dados do Burndown'!F2:F780,"<="&A16))) | E16: =IF('Dados do Burndown'!R14>TODAY(),"Futura",IF(F16>0,"Preencher datas de conclusão",IF('Dados do Burndown'!R14+6>TODAY(),"Em andamento",IF(OR(D16>0,COUNTIFS('Dados do Burndown'!E2:E780,A16,'Dados do Burndown'!C2:C780,FALSE)>0),"Há esforço pendente","Escopo concluído")))) -> Futura | F16: =COUNTIFS('Dados do Burndown'!E2:E780,A16,'Dados do Burndown'!B2:B780,">0",'Dados do Burndown'!C2:C780,TRUE,'Dados do Burndown'!D2:D780,"") -> 0
A17: 14 | B17: =SUMIF('Dados do Burndown'!E2:E780,A17,'Dados do Burndown'!B2:B780) -> 17.5 | C17: =MAX(0,B17-SUMIFS('Dados do Burndown'!B2:B780,'Dados do Burndown'!E2:E780,A17,'Dados do Burndown'!C2:C780,TRUE,'Dados do Burndown'!D2:D780,">0",'Dados do Burndown'!D2:D780,"<="&'Dados do Burndown'!R15-1)-SUMIFS('Dados do Burndown'!B2:B780,'Dados do Burndown'!E2:E780,A17,'Dados do Burndown'!C2:C780,TRUE,'Dados do Burndown'!D2:D780,"",'Dados do Burndown'!F2:F780,">0",'Dados do Burndown'!F2:F780,"<"&A17)) -> 17.5 | D17: =IF('Dados do Burndown'!R15+6>TODAY(),"",MAX(0,B17-SUMIFS('Dados do Burndown'!B2:B780,'Dados do Burndown'!E2:E780,A17,'Dados do Burndown'!C2:C780,TRUE,'Dados do Burndown'!D2:D780,">0",'Dados do Burndown'!D2:D780,"<="&'Dados do Burndown'!R15+6)-SUMIFS('Dados do Burndown'!B2:B780,'Dados do Burndown'!E2:E780,A17,'Dados do Burndown'!C2:C780,TRUE,'Dados do Burndown'!D2:D780,"",'Dados do Burndown'!F2:F780,">0",'Dados do Burndown'!F2:F780,"<="&A17))) | E17: =IF('Dados do Burndown'!R15>TODAY(),"Futura",IF(F17>0,"Preencher datas de conclusão",IF('Dados do Burndown'!R15+6>TODAY(),"Em andamento",IF(OR(D17>0,COUNTIFS('Dados do Burndown'!E2:E780,A17,'Dados do Burndown'!C2:C780,FALSE)>0),"Há esforço pendente","Escopo concluído")))) -> Futura | F17: =COUNTIFS('Dados do Burndown'!E2:E780,A17,'Dados do Burndown'!B2:B780,">0",'Dados do Burndown'!C2:C780,TRUE,'Dados do Burndown'!D2:D780,"") -> 0
A18: 15 | B18: =SUMIF('Dados do Burndown'!E2:E780,A18,'Dados do Burndown'!B2:B780) -> 38.5 | C18: =MAX(0,B18-SUMIFS('Dados do Burndown'!B2:B780,'Dados do Burndown'!E2:E780,A18,'Dados do Burndown'!C2:C780,TRUE,'Dados do Burndown'!D2:D780,">0",'Dados do Burndown'!D2:D780,"<="&'Dados do Burndown'!R16-1)-SUMIFS('Dados do Burndown'!B2:B780,'Dados do Burndown'!E2:E780,A18,'Dados do Burndown'!C2:C780,TRUE,'Dados do Burndown'!D2:D780,"",'Dados do Burndown'!F2:F780,">0",'Dados do Burndown'!F2:F780,"<"&A18)) -> 38.5 | D18: =IF('Dados do Burndown'!R16+6>TODAY(),"",MAX(0,B18-SUMIFS('Dados do Burndown'!B2:B780,'Dados do Burndown'!E2:E780,A18,'Dados do Burndown'!C2:C780,TRUE,'Dados do Burndown'!D2:D780,">0",'Dados do Burndown'!D2:D780,"<="&'Dados do Burndown'!R16+6)-SUMIFS('Dados do Burndown'!B2:B780,'Dados do Burndown'!E2:E780,A18,'Dados do Burndown'!C2:C780,TRUE,'Dados do Burndown'!D2:D780,"",'Dados do Burndown'!F2:F780,">0",'Dados do Burndown'!F2:F780,"<="&A18))) | E18: =IF('Dados do Burndown'!R16>TODAY(),"Futura",IF(F18>0,"Preencher datas de conclusão",IF('Dados do Burndown'!R16+6>TODAY(),"Em andamento",IF(OR(D18>0,COUNTIFS('Dados do Burndown'!E2:E780,A18,'Dados do Burndown'!C2:C780,FALSE)>0),"Há esforço pendente","Escopo concluído")))) -> Futura | F18: =COUNTIFS('Dados do Burndown'!E2:E780,A18,'Dados do Burndown'!B2:B780,">0",'Dados do Burndown'!C2:C780,TRUE,'Dados do Burndown'!D2:D780,"") -> 0
A19: 16 | B19: =SUMIF('Dados do Burndown'!E2:E780,A19,'Dados do Burndown'!B2:B780) -> 21 | C19: =MAX(0,B19-SUMIFS('Dados do Burndown'!B2:B780,'Dados do Burndown'!E2:E780,A19,'Dados do Burndown'!C2:C780,TRUE,'Dados do Burndown'!D2:D780,">0",'Dados do Burndown'!D2:D780,"<="&'Dados do Burndown'!R17-1)-SUMIFS('Dados do Burndown'!B2:B780,'Dados do Burndown'!E2:E780,A19,'Dados do Burndown'!C2:C780,TRUE,'Dados do Burndown'!D2:D780,"",'Dados do Burndown'!F2:F780,">0",'Dados do Burndown'!F2:F780,"<"&A19)) -> 21 | D19: =IF('Dados do Burndown'!R17+6>TODAY(),"",MAX(0,B19-SUMIFS('Dados do Burndown'!B2:B780,'Dados do Burndown'!E2:E780,A19,'Dados do Burndown'!C2:C780,TRUE,'Dados do Burndown'!D2:D780,">0",'Dados do Burndown'!D2:D780,"<="&'Dados do Burndown'!R17+6)-SUMIFS('Dados do Burndown'!B2:B780,'Dados do Burndown'!E2:E780,A19,'Dados do Burndown'!C2:C780,TRUE,'Dados do Burndown'!D2:D780,"",'Dados do Burndown'!F2:F780,">0",'Dados do Burndown'!F2:F780,"<="&A19))) | E19: =IF('Dados do Burndown'!R17>TODAY(),"Futura",IF(F19>0,"Preencher datas de conclusão",IF('Dados do Burndown'!R17+6>TODAY(),"Em andamento",IF(OR(D19>0,COUNTIFS('Dados do Burndown'!E2:E780,A19,'Dados do Burndown'!C2:C780,FALSE)>0),"Há esforço pendente","Escopo concluído")))) -> Futura | F19: =COUNTIFS('Dados do Burndown'!E2:E780,A19,'Dados do Burndown'!B2:B780,">0",'Dados do Burndown'!C2:C780,TRUE,'Dados do Burndown'!D2:D780,"") -> 0
A20: Ideal e real partem juntos no dia 0. A linha real desconta apenas tarefas planejadas e concluídas; pendências permanecem no saldo.
A23: Iteração 1
A24: Escopo planejado | B24: =B4 -> 24.5
A25: Situação | B25: =E4 -> Escopo concluído
A26: Início da iteração | B26: ='Dados do Burndown'!R2 -> 46244
A27: Fim da iteração | B27: =B26+6 -> 46250
A28: Datas pendentes | B28: =F4 -> 0
A30: Dia / data | B30: Ideal | C30: Real | D30: Dia da iteração
A31: Dia 0 | B31: =$C$4*(7-0)/7 -> 24.5 | C31: =$C$4 -> 24.5 | D31: 0
A32: =$B$26+0 -> 46244 | B32: =$C$4*(7-1)/7 -> 21 | C32: =IF(OR(A32>TODAY(),COUNTIFS('Dados do Burndown'!E2:E780,1,'Dados do Burndown'!B2:B780,">0",'Dados do Burndown'!C2:C780,TRUE,'Dados do Burndown'!D2:D780,"",'Dados do Burndown'!F2:F780,"")+COUNTIFS('Dados do Burndown'!E2:E780,1,'Dados do Burndown'!B2:B780,">0",'Dados do Burndown'!C2:C780,TRUE,'Dados do Burndown'!D2:D780,"",'Dados do Burndown'!F2:F780,1)>0),"",MAX(0,$B$4-SUMIFS('Dados do Burndown'!B2:B780,'Dados do Burndown'!E2:E780,1,'Dados do Burndown'!C2:C780,TRUE,'Dados do Burndown'!D2:D780,">0",'Dados do Burndown'!D2:D780,"<="&A32)-SUMIFS('Dados do Burndown'!B2:B780,'Dados do Burndown'!E2:E780,1,'Dados do Burndown'!C2:C780,TRUE,'Dados do Burndown'!D2:D780,"",'Dados do Burndown'!F2:F780,">0",'Dados do Burndown'!F2:F780,"<"&1))) -> 24.5 | D32: 1
A33: =$B$26+1 -> 46245 | B33: =$C$4*(7-2)/7 -> 17.5 | C33: =IF(OR(A33>TODAY(),COUNTIFS('Dados do Burndown'!E2:E780,1,'Dados do Burndown'!B2:B780,">0",'Dados do Burndown'!C2:C780,TRUE,'Dados do Burndown'!D2:D780,"",'Dados do Burndown'!F2:F780,"")+COUNTIFS('Dados do Burndown'!E2:E780,1,'Dados do Burndown'!B2:B780,">0",'Dados do Burndown'!C2:C780,TRUE,'Dados do Burndown'!D2:D780,"",'Dados do Burndown'!F2:F780,1)>0),"",MAX(0,$B$4-SUMIFS('Dados do Burndown'!B2:B780,'Dados do Burndown'!E2:E780,1,'Dados do Burndown'!C2:C780,TRUE,'Dados do Burndown'!D2:D780,">0",'Dados do Burndown'!D2:D780,"<="&A33)-SUMIFS('Dados do Burndown'!B2:B780,'Dados do Burndown'!E2:E780,1,'Dados do Burndown'!C2:C780,TRUE,'Dados do Burndown'!D2:D780,"",'Dados do Burndown'!F2:F780,">0",'Dados do Burndown'!F2:F780,"<"&1))) -> 24.5 | D33: 2
A34: =$B$26+2 -> 46246 | B34: =$C$4*(7-3)/7 -> 14 | C34: =IF(OR(A34>TODAY(),COUNTIFS('Dados do Burndown'!E2:E780,1,'Dados do Burndown'!B2:B780,">0",'Dados do Burndown'!C2:C780,TRUE,'Dados do Burndown'!D2:D780,"",'Dados do Burndown'!F2:F780,"")+COUNTIFS('Dados do Burndown'!E2:E780,1,'Dados do Burndown'!B2:B780,">0",'Dados do Burndown'!C2:C780,TRUE,'Dados do Burndown'!D2:D780,"",'Dados do Burndown'!F2:F780,1)>0),"",MAX(0,$B$4-SUMIFS('Dados do Burndown'!B2:B780,'Dados do Burndown'!E2:E780,1,'Dados do Burndown'!C2:C780,TRUE,'Dados do Burndown'!D2:D780,">0",'Dados do Burndown'!D2:D780,"<="&A34)-SUMIFS('Dados do Burndown'!B2:B780,'Dados do Burndown'!E2:E780,1,'Dados do Burndown'!C2:C780,TRUE,'Dados do Burndown'!D2:D780,"",'Dados do Burndown'!F2:F780,">0",'Dados do Burndown'!F2:F780,"<"&1))) -> 17.5 | D34: 3
A35: =$B$26+3 -> 46247 | B35: =$C$4*(7-4)/7 -> 10.5 | C35: =IF(OR(A35>TODAY(),COUNTIFS('Dados do Burndown'!E2:E780,1,'Dados do Burndown'!B2:B780,">0",'Dados do Burndown'!C2:C780,TRUE,'Dados do Burndown'!D2:D780,"",'Dados do Burndown'!F2:F780,"")+COUNTIFS('Dados do Burndown'!E2:E780,1,'Dados do Burndown'!B2:B780,">0",'Dados do Burndown'!C2:C780,TRUE,'Dados do Burndown'!D2:D780,"",'Dados do Burndown'!F2:F780,1)>0),"",MAX(0,$B$4-SUMIFS('Dados do Burndown'!B2:B780,'Dados do Burndown'!E2:E780,1,'Dados do Burndown'!C2:C780,TRUE,'Dados do Burndown'!D2:D780,">0",'Dados do Burndown'!D2:D780,"<="&A35)-SUMIFS('Dados do Burndown'!B2:B780,'Dados do Burndown'!E2:E780,1,'Dados do Burndown'!C2:C780,TRUE,'Dados do Burndown'!D2:D780,"",'Dados do Burndown'!F2:F780,">0",'Dados do Burndown'!F2:F780,"<"&1))) -> 17.5 | D35: 4
A36: =$B$26+4 -> 46248 | B36: =$C$4*(7-5)/7 -> 7 | C36: =IF(OR(A36>TODAY(),COUNTIFS('Dados do Burndown'!E2:E780,1,'Dados do Burndown'!B2:B780,">0",'Dados do Burndown'!C2:C780,TRUE,'Dados do Burndown'!D2:D780,"",'Dados do Burndown'!F2:F780,"")+COUNTIFS('Dados do Burndown'!E2:E780,1,'Dados do Burndown'!B2:B780,">0",'Dados do Burndown'!C2:C780,TRUE,'Dados do Burndown'!D2:D780,"",'Dados do Burndown'!F2:F780,1)>0),"",MAX(0,$B$4-SUMIFS('Dados do Burndown'!B2:B780,'Dados do Burndown'!E2:E780,1,'Dados do Burndown'!C2:C780,TRUE,'Dados do Burndown'!D2:D780,">0",'Dados do Burndown'!D2:D780,"<="&A36)-SUMIFS('Dados do Burndown'!B2:B780,'Dados do Burndown'!E2:E780,1,'Dados do Burndown'!C2:C780,TRUE,'Dados do Burndown'!D2:D780,"",'Dados do Burndown'!F2:F780,">0",'Dados do Burndown'!F2:F780,"<"&1))) -> 17.5 | D36: 5
A37: =$B$26+5 -> 46249 | B37: =$C$4*(7-6)/7 -> 3.5 | C37: =IF(OR(A37>TODAY(),COUNTIFS('Dados do Burndown'!E2:E780,1,'Dados do Burndown'!B2:B780,">0",'Dados do Burndown'!C2:C780,TRUE,'Dados do Burndown'!D2:D780,"",'Dados do Burndown'!F2:F780,"")+COUNTIFS('Dados do Burndown'!E2:E780,1,'Dados do Burndown'!B2:B780,">0",'Dados do Burndown'!C2:C780,TRUE,'Dados do Burndown'!D2:D780,"",'Dados do Burndown'!F2:F780,1)>0),"",MAX(0,$B$4-SUMIFS('Dados do Burndown'!B2:B780,'Dados do Burndown'!E2:E780,1,'Dados do Burndown'!C2:C780,TRUE,'Dados do Burndown'!D2:D780,">0",'Dados do Burndown'!D2:D780,"<="&A37)-SUMIFS('Dados do Burndown'!B2:B780,'Dados do Burndown'!E2:E780,1,'Dados do Burndown'!C2:C780,TRUE,'Dados do Burndown'!D2:D780,"",'Dados do Burndown'!F2:F780,">0",'Dados do Burndown'!F2:F780,"<"&1))) -> 0 | D37: 6
A38: =$B$26+6 -> 46250 | B38: =$C$4*(7-7)/7 -> 0 | C38: =IF(OR(A38>TODAY(),COUNTIFS('Dados do Burndown'!E2:E780,1,'Dados do Burndown'!B2:B780,">0",'Dados do Burndown'!C2:C780,TRUE,'Dados do Burndown'!D2:D780,"",'Dados do Burndown'!F2:F780,"")>0),"",MAX(0,$B$4-SUMIFS('Dados do Burndown'!B2:B780,'Dados do Burndown'!E2:E780,1,'Dados do Burndown'!C2:C780,TRUE,'Dados do Burndown'!D2:D780,">0",'Dados do Burndown'!D2:D780,"<="&A38)-SUMIFS('Dados do Burndown'!B2:B780,'Dados do Burndown'!E2:E780,1,'Dados do Burndown'!C2:C780,TRUE,'Dados do Burndown'!D2:D780,"",'Dados do Burndown'!F2:F780,">0",'Dados do Burndown'!F2:F780,"<="&1))) -> 0 | D38: 7
A44: Tarefas planejadas - concluídas e não concluídas | E44: Tarefas do escopo concluídas até o fim
A45: =IFERROR(__xludf.DUMMYFUNCTION("IFNA(TEXTJOIN(CHAR(10),TRUE,FILTER('Dados do Burndown'!A2:A780,'Dados do Burndown'!A2:A780<>"""",'Dados do Burndown'!E2:E780=1)),""Nenhuma tarefa planejada"")"),"4.2.3 Arquitetura e Divisão de Tarefas 4.2.1.1 Reunião Semanal 1") -> 4.2.3 Arquitetura e Divisão de Tarefas 4.2.1.1 Reunião Semanal 1 | E45: =IFERROR(__xludf.DUMMYFUNCTION("IFNA(TEXTJOIN(CHAR(10),TRUE,FILTER('Dados do Burndown'!A2:A780,'Dados do Burndown'!A2:A780<>"""",'Dados do Burndown'!E2:E780=1,'Dados do Burndown'!C2:C780=TRUE,((('Dados do Burndown'!D2:D780<=$B$27)*('Dados do Burndown'!D2:D780>0))+(('Dados do Burndown'!D"&"2:D780="""")*('Dados do Burndown'!F2:F780>0)*('Dados do Burndown'!F2:F780<=1)))>0)),""Nenhuma tarefa do escopo concluída"")"),"4.2.3 Arquitetura e Divisão de Tarefas 4.2.1.1 Reunião Semanal 1") -> 4.2.3 Arquitetura e Divisão de Tarefas 4.2.1.1 Reunião Semanal 1
A70: Iteração 2
A71: Escopo planejado | B71: =B5 -> 23.5
A72: Situação | B72: =E5 -> Há esforço pendente
...

Sheet Burndown
A1: Data Inicio | B1: Iteração | C1: Ideal Burndown | D1: Actual Burndown | E1: Tarefas Concluidas
A2: 46237 | B2: 0 | C2: =SUM('Base de Dados'!C:C) - SUM('Base de Dados'!C:C)*(B2)/16 -> 507.5 | D2: =SUM('Base de Dados'!C:C) - SUMIF('Base de Dados'!G:G,"<="&B2, 'Base de Dados'!C:C) - (B2*(40/15)) -> 507.5
A3: 46244 | B3: 1 | C3: =SUM('Base de Dados'!C:C) - SUM('Base de Dados'!C:C)*(B3)/16 -> 475.78125 | D3: =SUM('Base de Dados'!C:C) - SUMIF('Base de Dados'!G:G,"<="&B3, 'Base de Dados'!C:C) - (B3*(40/15)) -> 497.83333 | E3: =IFERROR(__xludf.DUMMYFUNCTION("IFERROR(TEXTJOIN(""; "",TRUE,FILTER('Base de Dados'!A:A,'Base de Dados'!G:G=B3))&""; Reunião Semanal ""&B3,""Reunião Semanal ""&B3)"),"4.2.3 Arquitetura e Divisão de Tarefas; Reunião Semanal 1") -> 4.2.3 Arquitetura e Divisão de Tarefas; Reunião Semanal 1
A4: 46251 | B4: 2 | C4: =SUM('Base de Dados'!C:C) - SUM('Base de Dados'!C:C)*(B4)/16 -> 444.0625 | D4: =SUM('Base de Dados'!C:C) - SUMIF('Base de Dados'!G:G,"<="&B4, 'Base de Dados'!C:C) - (B4*(40/15)) -> 495.16667 | E4: =IFERROR(__xludf.DUMMYFUNCTION("IFERROR(TEXTJOIN(""; "",TRUE,FILTER('Base de Dados'!A:A,'Base de Dados'!G:G=B4))&""; Reunião Semanal ""&B4,""Reunião Semanal ""&B4)"),"Reunião Semanal 2") -> Reunião Semanal 2
A5: 46258 | B5: 3 | C5: =SUM('Base de Dados'!C:C) - SUM('Base de Dados'!C:C)*(B5)/16 -> 412.34375 | D5: =SUM('Base de Dados'!C:C) - SUMIF('Base de Dados'!G:G,"<="&B5, 'Base de Dados'!C:C) - (B5*(40/15)) -> 478.5 | E5: =IFERROR(__xludf.DUMMYFUNCTION("IFERROR(TEXTJOIN(""; "",TRUE,FILTER('Base de Dados'!A:A,'Base de Dados'!G:G=B5))&""; Reunião Semanal ""&B5,""Reunião Semanal ""&B5)"),"4.1.1 EAP; 4.1.2.2 APF; 4.1.2.3 COCOMO; 4.3.2 Kanban; 4.4 Análise de Risco; Reunião Semanal 3") -> 4.1.1 EAP; 4.1.2.2 APF; 4.1.2.3 COCOMO; 4.3.2 Kanban; 4.4 Análise de Risco; Reunião Semanal 3
A6: 46265 | B6: 4 | C6: =SUM('Base de Dados'!C:C) - SUM('Base de Dados'!C:C)*(B6)/16 -> 380.625 | D6: =SUM('Base de Dados'!C:C) - SUMIF('Base de Dados'!G:G,"<="&B6, 'Base de Dados'!C:C) - (B6*(40/15)) -> 472.83333 | E6: =IFERROR(__xludf.DUMMYFUNCTION("IFERROR(TEXTJOIN(""; "",TRUE,FILTER('Base de Dados'!A:A,'Base de Dados'!G:G=B6))&""; Reunião Semanal ""&B6,""Reunião Semanal ""&B6)"),"4.1.2.1 Planning Poker; Reunião Semanal 4") -> 4.1.2.1 Planning Poker; Reunião Semanal 4
A7: 46272 | B7: 5 | C7: =SUM('Base de Dados'!C:C) - SUM('Base de Dados'!C:C)*(B7)/16 -> 348.90625 | D7: =SUM('Base de Dados'!C:C) - SUMIF('Base de Dados'!G:G,"<="&B7, 'Base de Dados'!C:C) - (B7*(40/15)) -> 454.66667 | E7: =IFERROR(__xludf.DUMMYFUNCTION("IFERROR(TEXTJOIN(""; "",TRUE,FILTER('Base de Dados'!A:A,'Base de Dados'!G:G=B7))&""; Reunião Semanal ""&B7,""Reunião Semanal ""&B7)"),"1.1.1 Layout da Página Principal; 1.1.2 Botões com Roteamento; 1.2.1 Layout da Página da Partida; 1.3.3 Seletor de Tema; 1.4.1 Layout da Página de Créditos; 1.4.2 Exibição das Tecnologias/Técnicas do Projeto; 1.4.3 Exibição da Equipe; 4.3.3 Roadmap (Gantt"&"); Reunião Semanal 5") -> 1.1.1 Layout da Página Principal; 1.1.2 Botões com Roteamento; 1.2.1 Layout da Página da Partida; 1.3.3 Seletor de Tema; 1.4.1 Layout da Página de Créditos; 1.4.2 Exibição das Tecnologias/Técnicas do Projeto; 1.4.3 Exibição da Equipe; 4.3.3 Roadmap (Gantt); Reunião Semanal 5
A8: 46279 | B8: 6 | C8: =SUM('Base de Dados'!C:C) - SUM('Base de Dados'!C:C)*(B8)/16 -> 317.1875 | D8: =SUM('Base de Dados'!C:C) - SUMIF('Base de Dados'!G:G,"<="&B8, 'Base de Dados'!C:C) - (B8*(40/15)) -> 445.5 | E8: =IFERROR(__xludf.DUMMYFUNCTION("IFERROR(TEXTJOIN(""; "",TRUE,FILTER('Base de Dados'!A:A,'Base de Dados'!G:G=B8))&""; Reunião Semanal ""&B8,""Reunião Semanal ""&B8)"),"1.2.2.2 Componentes das Peças; 4.2.2.1 1º Apresentação; Reunião Semanal 6") -> 1.2.2.2 Componentes das Peças; 4.2.2.1 1º Apresentação; Reunião Semanal 6
A9: 46286 | B9: 7 | C9: =SUM('Base de Dados'!C:C) - SUM('Base de Dados'!C:C)*(B9)/16 -> 285.46875
A10: 46293 | B10: 8 | C10: =SUM('Base de Dados'!C:C) - SUM('Base de Dados'!C:C)*(B10)/16 -> 253.75
A11: 46300 | B11: 9 | C11: =SUM('Base de Dados'!C:C) - SUM('Base de Dados'!C:C)*(B11)/16 -> 222.03125
A12: 46307 | B12: 10 | C12: =SUM('Base de Dados'!C:C) - SUM('Base de Dados'!C:C)*(B12)/16 -> 190.3125 | E12: =SUM('Base de Dados'!C:C) - SUM('Base de Dados'!C:C)*(B2)/16 -> 507.5
A13: 46314 | B13: 11 | C13: =SUM('Base de Dados'!C:C) - SUM('Base de Dados'!C:C)*(B13)/16 -> 158.59375
A14: 46321 | B14: 12 | C14: =SUM('Base de Dados'!C:C) - SUM('Base de Dados'!C:C)*(B14)/16 -> 126.875
A15: 46328 | B15: 13 | C15: =SUM('Base de Dados'!C:C) - SUM('Base de Dados'!C:C)*(B15)/16 -> 95.15625
A16: 46335 | B16: 14 | C16: =SUM('Base de Dados'!C:C) - SUM('Base de Dados'!C:C)*(B16)/16 -> 63.4375
A17: 46342 | B17: 15 | C17: =SUM('Base de Dados'!C:C) - SUM('Base de Dados'!C:C)*(B17)/16 -> 31.71875
A18: 46349 | B18: 16 | C18: =SUM('Base de Dados'!C:C) - SUM('Base de Dados'!C:C)*(B18)/16 -> 0
A20: Concluída
A21: Em andamento
A22: Futura

Sheet Dados do Burndown
A1: Tarefa | B1: Esforço planejado | C1: Concluída | D1: Data real | E1: Iteração planejada — Base H | F1: Iteração real sem data | J1: Reunião semanal | K1: Esforço por reunião | L1: Data de conclusão | Q1: Iteração | R1: Início
